[2021-08-19 17:06:23 +0900] [17616] [INFO] Starting gunicorn 20.1.0
[2021-08-19 17:06:23 +0900] [17616] [ERROR] Connection in use: ('0.0.0.0', 8000)
[2021-08-19 17:06:23 +0900] [17616] [ERROR] Retrying in 1 second.
[2021-08-19 17:06:24 +0900] [17616] [ERROR] Connection in use: ('0.0.0.0', 8000)
[2021-08-19 17:06:24 +0900] [17616] [ERROR] Retrying in 1 second.
[2021-08-19 17:06:25 +0900] [17616] [ERROR] Connection in use: ('0.0.0.0', 8000)
[2021-08-19 17:06:25 +0900] [17616] [ERROR] Retrying in 1 second.
[2021-08-19 17:06:26 +0900] [17616] [ERROR] Connection in use: ('0.0.0.0', 8000)
[2021-08-19 17:06:26 +0900] [17616] [ERROR] Retrying in 1 second.
[2021-08-19 17:06:27 +0900] [17616] [ERROR] Connection in use: ('0.0.0.0', 8000)
[2021-08-19 17:06:27 +0900] [17616] [ERROR] Retrying in 1 second.
[2021-08-19 17:06:28 +0900] [17616] [ERROR] Can't connect to ('0.0.0.0', 8000)
[2021-08-23 15:30:15 +0900] [2251] [INFO] Starting gunicorn 20.1.0
[2021-08-23 15:30:15 +0900] [2251] [INFO] Listening at: http://0.0.0.0:8000 (2251)
[2021-08-23 15:30:15 +0900] [2251] [INFO] Using worker: sync
[2021-08-23 15:30:15 +0900] [2254] [INFO] Booting worker with pid: 2254
[2021-08-23 22:27:38 +0900] [2251] [INFO] Handling signal: term
[2021-08-23 22:27:38 +0900] [2251] [WARNING] Worker with pid 2254 was terminated due to signal 1
[2021-08-23 22:27:38 +0900] [2251] [INFO] Shutting down: Master
[2021-08-24 12:37:02 +0900] [1654] [INFO] Starting gunicorn 20.1.0
[2021-08-24 12:37:02 +0900] [1654] [INFO] Listening at: http://0.0.0.0:8000 (1654)
[2021-08-24 12:37:02 +0900] [1654] [INFO] Using worker: sync
[2021-08-24 12:37:02 +0900] [1657] [INFO] Booting worker with pid: 1657
[2021-08-24 16:06:38 +0900] [1654] [CRITICAL] WORKER TIMEOUT (pid:1657)
[2021-08-24 16:06:38 +0900] [1657] [INFO] Worker exiting (pid: 1657)
[2021-08-24 16:06:38 +0900] [5076] [INFO] Booting worker with pid: 5076
[2021-08-24 16:13:15 +0900] [1654] [CRITICAL] WORKER TIMEOUT (pid:5076)
[2021-08-24 16:13:15 +0900] [5076] [INFO] Worker exiting (pid: 5076)
[2021-08-24 16:13:15 +0900] [5210] [INFO] Booting worker with pid: 5210
[2021-08-24 17:04:13 +0900] [6211] [INFO] Starting gunicorn 20.1.0
[2021-08-24 17:04:13 +0900] [6211] [ERROR] Connection in use: ('0.0.0.0', 8000)
[2021-08-24 17:04:13 +0900] [6211] [ERROR] Retrying in 1 second.
[2021-08-24 17:04:14 +0900] [6211] [ERROR] Connection in use: ('0.0.0.0', 8000)
[2021-08-24 17:04:14 +0900] [6211] [ERROR] Retrying in 1 second.
[2021-08-24 17:04:15 +0900] [6211] [ERROR] Connection in use: ('0.0.0.0', 8000)
[2021-08-24 17:04:15 +0900] [6211] [ERROR] Retrying in 1 second.
[2021-08-24 17:04:16 +0900] [6211] [ERROR] Connection in use: ('0.0.0.0', 8000)
[2021-08-24 17:04:16 +0900] [6211] [ERROR] Retrying in 1 second.
[2021-08-24 17:04:17 +0900] [6211] [ERROR] Connection in use: ('0.0.0.0', 8000)
[2021-08-24 17:04:17 +0900] [6211] [ERROR] Retrying in 1 second.
[2021-08-24 17:04:18 +0900] [6211] [ERROR] Can't connect to ('0.0.0.0', 8000)
[2021-08-24 17:20:32 +0900] [6867] [INFO] Starting gunicorn 20.1.0
[2021-08-24 17:20:32 +0900] [6867] [ERROR] Connection in use: ('0.0.0.0', 8000)
[2021-08-24 17:20:32 +0900] [6867] [ERROR] Retrying in 1 second.
[2021-08-24 17:20:33 +0900] [6867] [ERROR] Connection in use: ('0.0.0.0', 8000)
[2021-08-24 17:20:33 +0900] [6867] [ERROR] Retrying in 1 second.
[2021-08-24 17:20:34 +0900] [6867] [ERROR] Connection in use: ('0.0.0.0', 8000)
[2021-08-24 17:20:34 +0900] [6867] [ERROR] Retrying in 1 second.
[2021-08-24 17:20:35 +0900] [6867] [ERROR] Connection in use: ('0.0.0.0', 8000)
[2021-08-24 17:20:35 +0900] [6867] [ERROR] Retrying in 1 second.
[2021-08-24 17:20:36 +0900] [6867] [ERROR] Connection in use: ('0.0.0.0', 8000)
[2021-08-24 17:20:36 +0900] [6867] [ERROR] Retrying in 1 second.
[2021-08-24 17:20:37 +0900] [6867] [ERROR] Can't connect to ('0.0.0.0', 8000)
[2021-08-24 17:21:20 +0900] [1654] [CRITICAL] WORKER TIMEOUT (pid:5210)
[2021-08-24 17:21:20 +0900] [5210] [INFO] Worker exiting (pid: 5210)
[2021-08-24 17:21:20 +0900] [6890] [INFO] Booting worker with pid: 6890
[2021-08-24 17:21:20 +0900] [6890] [ERROR] Exception in worker process
Traceback (most recent call last):
  File "/home/uosselab/.local/lib/python3.6/site-packages/gunicorn/arbiter.py", line 589, in spawn_worker
    worker.init_process()
  File "/home/uosselab/.local/lib/python3.6/site-packages/gunicorn/workers/base.py", line 134, in init_process
    self.load_wsgi()
  File "/home/uosselab/.local/lib/python3.6/site-packages/gunicorn/workers/base.py", line 146, in load_wsgi
    self.wsgi = self.app.wsgi()
  File "/home/uosselab/.local/lib/python3.6/site-packages/gunicorn/app/base.py", line 67, in wsgi
    self.callable = self.load()
  File "/home/uosselab/.local/lib/python3.6/site-packages/gunicorn/app/wsgiapp.py", line 58, in load
    return self.load_wsgiapp()
  File "/home/uosselab/.local/lib/python3.6/site-packages/gunicorn/app/wsgiapp.py", line 48, in load_wsgiapp
    return util.import_app(self.app_uri)
  File "/home/uosselab/.local/lib/python3.6/site-packages/gunicorn/util.py", line 359, in import_app
    mod = importlib.import_module(module)
  File "/usr/lib/python3.6/importlib/__init__.py", line 126, in import_module
    return _bootstrap._gcd_import(name[level:], package, level)
  File "<frozen importlib._bootstrap>", line 994, in _gcd_import
  File "<frozen importlib._bootstrap>", line 971, in _find_and_load
  File "<frozen importlib._bootstrap>", line 955, in _find_and_load_unlocked
  File "<frozen importlib._bootstrap>", line 665, in _load_unlocked
  File "<frozen importlib._bootstrap_external>", line 674, in exec_module
  File "<frozen importlib._bootstrap_external>", line 781, in get_code
  File "<frozen importlib._bootstrap_external>", line 741, in source_to_code
  File "<frozen importlib._bootstrap>", line 219, in _call_with_frames_removed
  File "/home/uosselab/바탕화면/X_TWICE_AI/server.py", line 12
    PATH = ./My_model/New_Vgg_16.pt
           ^
SyntaxError: invalid syntax
[2021-08-24 17:21:20 +0900] [6890] [INFO] Worker exiting (pid: 6890)
[2021-08-24 17:21:20 +0900] [1654] [INFO] Shutting down: Master
[2021-08-24 17:21:20 +0900] [1654] [INFO] Reason: Worker failed to boot.
[2021-08-24 17:22:49 +0900] [6951] [INFO] Starting gunicorn 20.1.0
[2021-08-24 17:22:49 +0900] [6951] [INFO] Listening at: http://0.0.0.0:8000 (6951)
[2021-08-24 17:22:49 +0900] [6951] [INFO] Using worker: sync
[2021-08-24 17:22:49 +0900] [6954] [INFO] Booting worker with pid: 6954
[2021-08-24 17:22:49 +0900] [6954] [ERROR] Exception in worker process
Traceback (most recent call last):
  File "/home/uosselab/.local/lib/python3.6/site-packages/gunicorn/arbiter.py", line 589, in spawn_worker
    worker.init_process()
  File "/home/uosselab/.local/lib/python3.6/site-packages/gunicorn/workers/base.py", line 134, in init_process
    self.load_wsgi()
  File "/home/uosselab/.local/lib/python3.6/site-packages/gunicorn/workers/base.py", line 146, in load_wsgi
    self.wsgi = self.app.wsgi()
  File "/home/uosselab/.local/lib/python3.6/site-packages/gunicorn/app/base.py", line 67, in wsgi
    self.callable = self.load()
  File "/home/uosselab/.local/lib/python3.6/site-packages/gunicorn/app/wsgiapp.py", line 58, in load
    return self.load_wsgiapp()
  File "/home/uosselab/.local/lib/python3.6/site-packages/gunicorn/app/wsgiapp.py", line 48, in load_wsgiapp
    return util.import_app(self.app_uri)
  File "/home/uosselab/.local/lib/python3.6/site-packages/gunicorn/util.py", line 359, in import_app
    mod = importlib.import_module(module)
  File "/usr/lib/python3.6/importlib/__init__.py", line 126, in import_module
    return _bootstrap._gcd_import(name[level:], package, level)
  File "<frozen importlib._bootstrap>", line 994, in _gcd_import
  File "<frozen importlib._bootstrap>", line 971, in _find_and_load
  File "<frozen importlib._bootstrap>", line 955, in _find_and_load_unlocked
  File "<frozen importlib._bootstrap>", line 665, in _load_unlocked
  File "<frozen importlib._bootstrap_external>", line 674, in exec_module
  File "<frozen importlib._bootstrap_external>", line 781, in get_code
  File "<frozen importlib._bootstrap_external>", line 741, in source_to_code
  File "<frozen importlib._bootstrap>", line 219, in _call_with_frames_removed
  File "/home/uosselab/바탕화면/X_TWICE_AI/server.py", line 13
    PATH = ./My_model/New_Vgg_16.pt
           ^
SyntaxError: invalid syntax
[2021-08-24 17:22:49 +0900] [6954] [INFO] Worker exiting (pid: 6954)
[2021-08-24 17:22:49 +0900] [6951] [INFO] Shutting down: Master
[2021-08-24 17:22:49 +0900] [6951] [INFO] Reason: Worker failed to boot.
[2021-08-24 17:23:00 +0900] [6963] [INFO] Starting gunicorn 20.1.0
[2021-08-24 17:23:00 +0900] [6963] [INFO] Listening at: http://0.0.0.0:8000 (6963)
[2021-08-24 17:23:00 +0900] [6963] [INFO] Using worker: sync
[2021-08-24 17:23:00 +0900] [6966] [INFO] Booting worker with pid: 6966
[2021-08-24 17:23:00 +0900] [6966] [ERROR] Exception in worker process
Traceback (most recent call last):
  File "/home/uosselab/.local/lib/python3.6/site-packages/gunicorn/arbiter.py", line 589, in spawn_worker
    worker.init_process()
  File "/home/uosselab/.local/lib/python3.6/site-packages/gunicorn/workers/base.py", line 134, in init_process
    self.load_wsgi()
  File "/home/uosselab/.local/lib/python3.6/site-packages/gunicorn/workers/base.py", line 146, in load_wsgi
    self.wsgi = self.app.wsgi()
  File "/home/uosselab/.local/lib/python3.6/site-packages/gunicorn/app/base.py", line 67, in wsgi
    self.callable = self.load()
  File "/home/uosselab/.local/lib/python3.6/site-packages/gunicorn/app/wsgiapp.py", line 58, in load
    return self.load_wsgiapp()
  File "/home/uosselab/.local/lib/python3.6/site-packages/gunicorn/app/wsgiapp.py", line 48, in load_wsgiapp
    return util.import_app(self.app_uri)
  File "/home/uosselab/.local/lib/python3.6/site-packages/gunicorn/util.py", line 359, in import_app
    mod = importlib.import_module(module)
  File "/usr/lib/python3.6/importlib/__init__.py", line 126, in import_module
    return _bootstrap._gcd_import(name[level:], package, level)
  File "<frozen importlib._bootstrap>", line 994, in _gcd_import
  File "<frozen importlib._bootstrap>", line 971, in _find_and_load
  File "<frozen importlib._bootstrap>", line 955, in _find_and_load_unlocked
  File "<frozen importlib._bootstrap>", line 665, in _load_unlocked
  File "<frozen importlib._bootstrap_external>", line 674, in exec_module
  File "<frozen importlib._bootstrap_external>", line 781, in get_code
  File "<frozen importlib._bootstrap_external>", line 741, in source_to_code
  File "<frozen importlib._bootstrap>", line 219, in _call_with_frames_removed
  File "/home/uosselab/바탕화면/X_TWICE_AI/server.py", line 13
    PATH = ./My_model/New_Vgg_16.pt
           ^
SyntaxError: invalid syntax
[2021-08-24 17:23:00 +0900] [6966] [INFO] Worker exiting (pid: 6966)
[2021-08-24 17:23:00 +0900] [6963] [INFO] Shutting down: Master
[2021-08-24 17:23:00 +0900] [6963] [INFO] Reason: Worker failed to boot.
[2021-08-24 17:24:10 +0900] [6979] [INFO] Starting gunicorn 20.1.0
[2021-08-24 17:24:10 +0900] [6979] [INFO] Listening at: http://0.0.0.0:8000 (6979)
[2021-08-24 17:24:10 +0900] [6979] [INFO] Using worker: sync
[2021-08-24 17:24:10 +0900] [6982] [INFO] Booting worker with pid: 6982
[2021-08-24 17:24:10 +0900] [6982] [ERROR] Exception in worker process
Traceback (most recent call last):
  File "/home/uosselab/.local/lib/python3.6/site-packages/gunicorn/arbiter.py", line 589, in spawn_worker
    worker.init_process()
  File "/home/uosselab/.local/lib/python3.6/site-packages/gunicorn/workers/base.py", line 134, in init_process
    self.load_wsgi()
  File "/home/uosselab/.local/lib/python3.6/site-packages/gunicorn/workers/base.py", line 146, in load_wsgi
    self.wsgi = self.app.wsgi()
  File "/home/uosselab/.local/lib/python3.6/site-packages/gunicorn/app/base.py", line 67, in wsgi
    self.callable = self.load()
  File "/home/uosselab/.local/lib/python3.6/site-packages/gunicorn/app/wsgiapp.py", line 58, in load
    return self.load_wsgiapp()
  File "/home/uosselab/.local/lib/python3.6/site-packages/gunicorn/app/wsgiapp.py", line 48, in load_wsgiapp
    return util.import_app(self.app_uri)
  File "/home/uosselab/.local/lib/python3.6/site-packages/gunicorn/util.py", line 359, in import_app
    mod = importlib.import_module(module)
  File "/usr/lib/python3.6/importlib/__init__.py", line 126, in import_module
    return _bootstrap._gcd_import(name[level:], package, level)
  File "<frozen importlib._bootstrap>", line 994, in _gcd_import
  File "<frozen importlib._bootstrap>", line 971, in _find_and_load
  File "<frozen importlib._bootstrap>", line 955, in _find_and_load_unlocked
  File "<frozen importlib._bootstrap>", line 665, in _load_unlocked
  File "<frozen importlib._bootstrap_external>", line 674, in exec_module
  File "<frozen importlib._bootstrap_external>", line 781, in get_code
  File "<frozen importlib._bootstrap_external>", line 741, in source_to_code
  File "<frozen importlib._bootstrap>", line 219, in _call_with_frames_removed
  File "/home/uosselab/바탕화면/X_TWICE_AI/server.py", line 13
    PATH = ./My_model/New_Vgg_16.pt
           ^
SyntaxError: invalid syntax
[2021-08-24 17:24:10 +0900] [6982] [INFO] Worker exiting (pid: 6982)
[2021-08-24 17:24:10 +0900] [6979] [INFO] Shutting down: Master
[2021-08-24 17:24:10 +0900] [6979] [INFO] Reason: Worker failed to boot.
[2021-08-24 17:25:32 +0900] [8364] [INFO] Starting gunicorn 20.1.0
[2021-08-24 17:25:32 +0900] [8364] [INFO] Listening at: http://0.0.0.0:8000 (8364)
[2021-08-24 17:25:32 +0900] [8364] [INFO] Using worker: sync
[2021-08-24 17:25:32 +0900] [8367] [INFO] Booting worker with pid: 8367
[2021-08-24 17:25:32 +0900] [8367] [ERROR] Exception in worker process
Traceback (most recent call last):
  File "/home/uosselab/.local/lib/python3.6/site-packages/gunicorn/arbiter.py", line 589, in spawn_worker
    worker.init_process()
  File "/home/uosselab/.local/lib/python3.6/site-packages/gunicorn/workers/base.py", line 134, in init_process
    self.load_wsgi()
  File "/home/uosselab/.local/lib/python3.6/site-packages/gunicorn/workers/base.py", line 146, in load_wsgi
    self.wsgi = self.app.wsgi()
  File "/home/uosselab/.local/lib/python3.6/site-packages/gunicorn/app/base.py", line 67, in wsgi
    self.callable = self.load()
  File "/home/uosselab/.local/lib/python3.6/site-packages/gunicorn/app/wsgiapp.py", line 58, in load
    return self.load_wsgiapp()
  File "/home/uosselab/.local/lib/python3.6/site-packages/gunicorn/app/wsgiapp.py", line 48, in load_wsgiapp
    return util.import_app(self.app_uri)
  File "/home/uosselab/.local/lib/python3.6/site-packages/gunicorn/util.py", line 359, in import_app
    mod = importlib.import_module(module)
  File "/usr/lib/python3.6/importlib/__init__.py", line 126, in import_module
    return _bootstrap._gcd_import(name[level:], package, level)
  File "<frozen importlib._bootstrap>", line 994, in _gcd_import
  File "<frozen importlib._bootstrap>", line 971, in _find_and_load
  File "<frozen importlib._bootstrap>", line 955, in _find_and_load_unlocked
  File "<frozen importlib._bootstrap>", line 665, in _load_unlocked
  File "<frozen importlib._bootstrap_external>", line 674, in exec_module
  File "<frozen importlib._bootstrap_external>", line 781, in get_code
  File "<frozen importlib._bootstrap_external>", line 741, in source_to_code
  File "<frozen importlib._bootstrap>", line 219, in _call_with_frames_removed
  File "/home/uosselab/바탕화면/X_TWICE_AI/server.py", line 13
    PATH = ./My_model/New_Vgg_16.pt
           ^
SyntaxError: invalid syntax
[2021-08-24 17:25:32 +0900] [8367] [INFO] Worker exiting (pid: 8367)
[2021-08-24 17:25:32 +0900] [8364] [INFO] Shutting down: Master
[2021-08-24 17:25:32 +0900] [8364] [INFO] Reason: Worker failed to boot.
[2021-08-24 17:25:57 +0900] [8521] [INFO] Starting gunicorn 20.1.0
[2021-08-24 17:25:57 +0900] [8521] [INFO] Listening at: http://0.0.0.0:8000 (8521)
[2021-08-24 17:25:57 +0900] [8521] [INFO] Using worker: sync
[2021-08-24 17:25:57 +0900] [8524] [INFO] Booting worker with pid: 8524
[2021-08-24 17:25:57 +0900] [8524] [ERROR] Exception in worker process
Traceback (most recent call last):
  File "/home/uosselab/.local/lib/python3.6/site-packages/gunicorn/arbiter.py", line 589, in spawn_worker
    worker.init_process()
  File "/home/uosselab/.local/lib/python3.6/site-packages/gunicorn/workers/base.py", line 134, in init_process
    self.load_wsgi()
  File "/home/uosselab/.local/lib/python3.6/site-packages/gunicorn/workers/base.py", line 146, in load_wsgi
    self.wsgi = self.app.wsgi()
  File "/home/uosselab/.local/lib/python3.6/site-packages/gunicorn/app/base.py", line 67, in wsgi
    self.callable = self.load()
  File "/home/uosselab/.local/lib/python3.6/site-packages/gunicorn/app/wsgiapp.py", line 58, in load
    return self.load_wsgiapp()
  File "/home/uosselab/.local/lib/python3.6/site-packages/gunicorn/app/wsgiapp.py", line 48, in load_wsgiapp
    return util.import_app(self.app_uri)
  File "/home/uosselab/.local/lib/python3.6/site-packages/gunicorn/util.py", line 359, in import_app
    mod = importlib.import_module(module)
  File "/usr/lib/python3.6/importlib/__init__.py", line 126, in import_module
    return _bootstrap._gcd_import(name[level:], package, level)
  File "<frozen importlib._bootstrap>", line 994, in _gcd_import
  File "<frozen importlib._bootstrap>", line 971, in _find_and_load
  File "<frozen importlib._bootstrap>", line 955, in _find_and_load_unlocked
  File "<frozen importlib._bootstrap>", line 665, in _load_unlocked
  File "<frozen importlib._bootstrap_external>", line 674, in exec_module
  File "<frozen importlib._bootstrap_external>", line 781, in get_code
  File "<frozen importlib._bootstrap_external>", line 741, in source_to_code
  File "<frozen importlib._bootstrap>", line 219, in _call_with_frames_removed
  File "/home/uosselab/바탕화면/X_TWICE_AI/server.py", line 13
    PATH = ./My_model/New_Vgg_16.pt
           ^
SyntaxError: invalid syntax
[2021-08-24 17:25:57 +0900] [8524] [INFO] Worker exiting (pid: 8524)
[2021-08-24 17:25:57 +0900] [8521] [INFO] Shutting down: Master
[2021-08-24 17:25:57 +0900] [8521] [INFO] Reason: Worker failed to boot.
[2021-08-24 17:27:46 +0900] [8920] [INFO] Starting gunicorn 20.1.0
[2021-08-24 17:27:46 +0900] [8920] [INFO] Listening at: http://0.0.0.0:8000 (8920)
[2021-08-24 17:27:46 +0900] [8920] [INFO] Using worker: sync
[2021-08-24 17:27:46 +0900] [8923] [INFO] Booting worker with pid: 8923
[2021-08-24 17:28:20 +0900] [8920] [CRITICAL] WORKER TIMEOUT (pid:8923)
[2021-08-24 17:28:20 +0900] [8923] [INFO] Worker exiting (pid: 8923)
[2021-08-24 17:28:20 +0900] [9002] [INFO] Booting worker with pid: 9002
[2021-08-24 17:28:20,566] ERROR in app: Exception on /predict [POST]
Traceback (most recent call last):
  File "/home/uosselab/.local/lib/python3.6/site-packages/flask/app.py", line 2311, in wsgi_app
    response = self.full_dispatch_request()
  File "/home/uosselab/.local/lib/python3.6/site-packages/flask/app.py", line 1834, in full_dispatch_request
    rv = self.handle_user_exception(e)
  File "/home/uosselab/.local/lib/python3.6/site-packages/flask/app.py", line 1737, in handle_user_exception
    reraise(exc_type, exc_value, tb)
  File "/home/uosselab/.local/lib/python3.6/site-packages/flask/_compat.py", line 36, in reraise
    raise value
  File "/home/uosselab/.local/lib/python3.6/site-packages/flask/app.py", line 1832, in full_dispatch_request
    rv = self.dispatch_request()
  File "/home/uosselab/.local/lib/python3.6/site-packages/flask/app.py", line 1818, in dispatch_request
    return self.view_functions[rule.endpoint](**req.view_args)
  File "/home/uosselab/바탕화면/X_TWICE_AI/server.py", line 52, in predict
    prediction = Image_Prediction(PATH, image_bytes=img_bytes)
TypeError: __init__() got an unexpected keyword argument 'image_bytes'
[2021-08-24 17:28:44,219] ERROR in app: Exception on /predict [POST]
Traceback (most recent call last):
  File "/home/uosselab/.local/lib/python3.6/site-packages/flask/app.py", line 2311, in wsgi_app
    response = self.full_dispatch_request()
  File "/home/uosselab/.local/lib/python3.6/site-packages/flask/app.py", line 1834, in full_dispatch_request
    rv = self.handle_user_exception(e)
  File "/home/uosselab/.local/lib/python3.6/site-packages/flask/app.py", line 1737, in handle_user_exception
    reraise(exc_type, exc_value, tb)
  File "/home/uosselab/.local/lib/python3.6/site-packages/flask/_compat.py", line 36, in reraise
    raise value
  File "/home/uosselab/.local/lib/python3.6/site-packages/flask/app.py", line 1832, in full_dispatch_request
    rv = self.dispatch_request()
  File "/home/uosselab/.local/lib/python3.6/site-packages/flask/app.py", line 1818, in dispatch_request
    return self.view_functions[rule.endpoint](**req.view_args)
  File "/home/uosselab/바탕화면/X_TWICE_AI/server.py", line 52, in predict
    prediction = Image_Prediction(PATH, image_bytes=img_bytes)
TypeError: __init__() got an unexpected keyword argument 'image_bytes'
[2021-08-24 17:28:52 +0900] [9084] [INFO] Starting gunicorn 20.1.0
[2021-08-24 17:28:52 +0900] [9084] [ERROR] Connection in use: ('0.0.0.0', 8000)
[2021-08-24 17:28:52 +0900] [9084] [ERROR] Retrying in 1 second.
[2021-08-24 17:28:53 +0900] [9084] [ERROR] Connection in use: ('0.0.0.0', 8000)
[2021-08-24 17:28:53 +0900] [9084] [ERROR] Retrying in 1 second.
[2021-08-24 17:28:54 +0900] [9084] [ERROR] Connection in use: ('0.0.0.0', 8000)
[2021-08-24 17:28:54 +0900] [9084] [ERROR] Retrying in 1 second.
[2021-08-24 17:28:55 +0900] [9084] [ERROR] Connection in use: ('0.0.0.0', 8000)
[2021-08-24 17:28:55 +0900] [9084] [ERROR] Retrying in 1 second.
[2021-08-24 17:28:56 +0900] [9084] [ERROR] Connection in use: ('0.0.0.0', 8000)
[2021-08-24 17:28:56 +0900] [9084] [ERROR] Retrying in 1 second.
[2021-08-24 17:28:57 +0900] [9084] [ERROR] Can't connect to ('0.0.0.0', 8000)
[2021-08-24 17:29:27 +0900] [8920] [CRITICAL] WORKER TIMEOUT (pid:9002)
[2021-08-24 17:29:27 +0900] [9002] [INFO] Worker exiting (pid: 9002)
[2021-08-24 17:29:27 +0900] [9161] [INFO] Booting worker with pid: 9161
[2021-08-24 17:29:27,787] ERROR in app: Exception on /predict [POST]
Traceback (most recent call last):
  File "/home/uosselab/.local/lib/python3.6/site-packages/flask/app.py", line 2311, in wsgi_app
    response = self.full_dispatch_request()
  File "/home/uosselab/.local/lib/python3.6/site-packages/flask/app.py", line 1834, in full_dispatch_request
    rv = self.handle_user_exception(e)
  File "/home/uosselab/.local/lib/python3.6/site-packages/flask/app.py", line 1737, in handle_user_exception
    reraise(exc_type, exc_value, tb)
  File "/home/uosselab/.local/lib/python3.6/site-packages/flask/_compat.py", line 36, in reraise
    raise value
  File "/home/uosselab/.local/lib/python3.6/site-packages/flask/app.py", line 1832, in full_dispatch_request
    rv = self.dispatch_request()
  File "/home/uosselab/.local/lib/python3.6/site-packages/flask/app.py", line 1818, in dispatch_request
    return self.view_functions[rule.endpoint](**req.view_args)
  File "/home/uosselab/바탕화면/X_TWICE_AI/server.py", line 52, in predict
    prediction = Image_Prediction(PATH, image_bytes=img_bytes)
TypeError: __init__() got an unexpected keyword argument 'image_bytes'
[2021-08-24 17:29:54 +0900] [9221] [INFO] Starting gunicorn 20.1.0
[2021-08-24 17:29:54 +0900] [9221] [ERROR] Connection in use: ('0.0.0.0', 8000)
[2021-08-24 17:29:54 +0900] [9221] [ERROR] Retrying in 1 second.
[2021-08-24 17:29:55 +0900] [9221] [ERROR] Connection in use: ('0.0.0.0', 8000)
[2021-08-24 17:29:55 +0900] [9221] [ERROR] Retrying in 1 second.
[2021-08-24 17:29:56,412] ERROR in app: Exception on /predict [POST]
Traceback (most recent call last):
  File "/home/uosselab/.local/lib/python3.6/site-packages/flask/app.py", line 2311, in wsgi_app
    response = self.full_dispatch_request()
  File "/home/uosselab/.local/lib/python3.6/site-packages/flask/app.py", line 1834, in full_dispatch_request
    rv = self.handle_user_exception(e)
  File "/home/uosselab/.local/lib/python3.6/site-packages/flask/app.py", line 1737, in handle_user_exception
    reraise(exc_type, exc_value, tb)
  File "/home/uosselab/.local/lib/python3.6/site-packages/flask/_compat.py", line 36, in reraise
    raise value
  File "/home/uosselab/.local/lib/python3.6/site-packages/flask/app.py", line 1832, in full_dispatch_request
    rv = self.dispatch_request()
  File "/home/uosselab/.local/lib/python3.6/site-packages/flask/app.py", line 1818, in dispatch_request
    return self.view_functions[rule.endpoint](**req.view_args)
  File "/home/uosselab/바탕화면/X_TWICE_AI/server.py", line 52, in predict
    #prediction = Image_Prediction(PATH, image_bytes=img_bytes)
TypeError: __init__() got an unexpected keyword argument 'image_bytes'
[2021-08-24 17:29:56 +0900] [9221] [ERROR] Connection in use: ('0.0.0.0', 8000)
[2021-08-24 17:29:56 +0900] [9221] [ERROR] Retrying in 1 second.
[2021-08-24 17:29:57,595] ERROR in app: Exception on /predict [POST]
Traceback (most recent call last):
  File "/home/uosselab/.local/lib/python3.6/site-packages/flask/app.py", line 2311, in wsgi_app
    response = self.full_dispatch_request()
  File "/home/uosselab/.local/lib/python3.6/site-packages/flask/app.py", line 1834, in full_dispatch_request
    rv = self.handle_user_exception(e)
  File "/home/uosselab/.local/lib/python3.6/site-packages/flask/app.py", line 1737, in handle_user_exception
    reraise(exc_type, exc_value, tb)
  File "/home/uosselab/.local/lib/python3.6/site-packages/flask/_compat.py", line 36, in reraise
    raise value
  File "/home/uosselab/.local/lib/python3.6/site-packages/flask/app.py", line 1832, in full_dispatch_request
    rv = self.dispatch_request()
  File "/home/uosselab/.local/lib/python3.6/site-packages/flask/app.py", line 1818, in dispatch_request
    return self.view_functions[rule.endpoint](**req.view_args)
  File "/home/uosselab/바탕화면/X_TWICE_AI/server.py", line 52, in predict
    #prediction = Image_Prediction(PATH, image_bytes=img_bytes)
TypeError: __init__() got an unexpected keyword argument 'image_bytes'
[2021-08-24 17:29:57 +0900] [9221] [ERROR] Connection in use: ('0.0.0.0', 8000)
[2021-08-24 17:29:57 +0900] [9221] [ERROR] Retrying in 1 second.
[2021-08-24 17:29:58 +0900] [9221] [ERROR] Connection in use: ('0.0.0.0', 8000)
[2021-08-24 17:29:58 +0900] [9221] [ERROR] Retrying in 1 second.
[2021-08-24 17:29:58,959] ERROR in app: Exception on /predict [POST]
Traceback (most recent call last):
  File "/home/uosselab/.local/lib/python3.6/site-packages/flask/app.py", line 2311, in wsgi_app
    response = self.full_dispatch_request()
  File "/home/uosselab/.local/lib/python3.6/site-packages/flask/app.py", line 1834, in full_dispatch_request
    rv = self.handle_user_exception(e)
  File "/home/uosselab/.local/lib/python3.6/site-packages/flask/app.py", line 1737, in handle_user_exception
    reraise(exc_type, exc_value, tb)
  File "/home/uosselab/.local/lib/python3.6/site-packages/flask/_compat.py", line 36, in reraise
    raise value
  File "/home/uosselab/.local/lib/python3.6/site-packages/flask/app.py", line 1832, in full_dispatch_request
    rv = self.dispatch_request()
  File "/home/uosselab/.local/lib/python3.6/site-packages/flask/app.py", line 1818, in dispatch_request
    return self.view_functions[rule.endpoint](**req.view_args)
  File "/home/uosselab/바탕화면/X_TWICE_AI/server.py", line 52, in predict
    #prediction = Image_Prediction(PATH, image_bytes=img_bytes)
TypeError: __init__() got an unexpected keyword argument 'image_bytes'
[2021-08-24 17:29:59 +0900] [9221] [ERROR] Can't connect to ('0.0.0.0', 8000)
[2021-08-24 17:30:01,073] ERROR in app: Exception on /predict [POST]
Traceback (most recent call last):
  File "/home/uosselab/.local/lib/python3.6/site-packages/flask/app.py", line 2311, in wsgi_app
    response = self.full_dispatch_request()
  File "/home/uosselab/.local/lib/python3.6/site-packages/flask/app.py", line 1834, in full_dispatch_request
    rv = self.handle_user_exception(e)
  File "/home/uosselab/.local/lib/python3.6/site-packages/flask/app.py", line 1737, in handle_user_exception
    reraise(exc_type, exc_value, tb)
  File "/home/uosselab/.local/lib/python3.6/site-packages/flask/_compat.py", line 36, in reraise
    raise value
  File "/home/uosselab/.local/lib/python3.6/site-packages/flask/app.py", line 1832, in full_dispatch_request
    rv = self.dispatch_request()
  File "/home/uosselab/.local/lib/python3.6/site-packages/flask/app.py", line 1818, in dispatch_request
    return self.view_functions[rule.endpoint](**req.view_args)
  File "/home/uosselab/바탕화면/X_TWICE_AI/server.py", line 52, in predict
    #prediction = Image_Prediction(PATH, image_bytes=img_bytes)
TypeError: __init__() got an unexpected keyword argument 'image_bytes'
[2021-08-24 17:30:36 +0900] [8920] [CRITICAL] WORKER TIMEOUT (pid:9161)
[2021-08-24 17:30:36 +0900] [9161] [INFO] Worker exiting (pid: 9161)
[2021-08-24 17:30:36 +0900] [9286] [INFO] Booting worker with pid: 9286
[2021-08-24 17:30:49,644] ERROR in app: Exception on /predict [POST]
Traceback (most recent call last):
  File "/home/uosselab/.local/lib/python3.6/site-packages/flask/app.py", line 2311, in wsgi_app
    response = self.full_dispatch_request()
  File "/home/uosselab/.local/lib/python3.6/site-packages/flask/app.py", line 1834, in full_dispatch_request
    rv = self.handle_user_exception(e)
  File "/home/uosselab/.local/lib/python3.6/site-packages/flask/app.py", line 1737, in handle_user_exception
    reraise(exc_type, exc_value, tb)
  File "/home/uosselab/.local/lib/python3.6/site-packages/flask/_compat.py", line 36, in reraise
    raise value
  File "/home/uosselab/.local/lib/python3.6/site-packages/flask/app.py", line 1832, in full_dispatch_request
    rv = self.dispatch_request()
  File "/home/uosselab/.local/lib/python3.6/site-packages/flask/app.py", line 1818, in dispatch_request
    return self.view_functions[rule.endpoint](**req.view_args)
  File "/home/uosselab/바탕화면/X_TWICE_AI/server.py", line 53, in predict
    prediction = Image_Prediction(PATH, file)
  File "/home/uosselab/바탕화면/X_TWICE_AI/image_prediction.py", line 19, in __init__
    self.current_vector, self.current_norm = self.GetFeatureVector(image)
  File "/home/uosselab/바탕화면/X_TWICE_AI/image_prediction.py", line 24, in GetFeatureVector
    trans_image = self.transform(image).to(self.cuda)
  File "/home/uosselab/.local/lib/python3.6/site-packages/torchvision/transforms/transforms.py", line 60, in __call__
    img = t(img)
  File "/home/uosselab/.local/lib/python3.6/site-packages/torch/nn/modules/module.py", line 889, in _call_impl
    result = self.forward(*input, **kwargs)
  File "/home/uosselab/.local/lib/python3.6/site-packages/torchvision/transforms/transforms.py", line 273, in forward
    return F.resize(img, self.size, self.interpolation)
  File "/home/uosselab/.local/lib/python3.6/site-packages/torchvision/transforms/functional.py", line 375, in resize
    return F_pil.resize(img, size=size, interpolation=pil_interpolation)
  File "/home/uosselab/.local/lib/python3.6/site-packages/torchvision/transforms/functional_pil.py", line 209, in resize
    raise TypeError('img should be PIL Image. Got {}'.format(type(img)))
TypeError: img should be PIL Image. Got <class 'werkzeug.datastructures.FileStorage'>
[2021-08-24 17:30:53 +0900] [9342] [INFO] Starting gunicorn 20.1.0
[2021-08-24 17:30:53 +0900] [9342] [ERROR] Connection in use: ('0.0.0.0', 8000)
[2021-08-24 17:30:53 +0900] [9342] [ERROR] Retrying in 1 second.
[2021-08-24 17:30:54 +0900] [9342] [ERROR] Connection in use: ('0.0.0.0', 8000)
[2021-08-24 17:30:54 +0900] [9342] [ERROR] Retrying in 1 second.
[2021-08-24 17:30:54,263] ERROR in app: Exception on /predict [POST]
Traceback (most recent call last):
  File "/home/uosselab/.local/lib/python3.6/site-packages/flask/app.py", line 2311, in wsgi_app
    response = self.full_dispatch_request()
  File "/home/uosselab/.local/lib/python3.6/site-packages/flask/app.py", line 1834, in full_dispatch_request
    rv = self.handle_user_exception(e)
  File "/home/uosselab/.local/lib/python3.6/site-packages/flask/app.py", line 1737, in handle_user_exception
    reraise(exc_type, exc_value, tb)
  File "/home/uosselab/.local/lib/python3.6/site-packages/flask/_compat.py", line 36, in reraise
    raise value
  File "/home/uosselab/.local/lib/python3.6/site-packages/flask/app.py", line 1832, in full_dispatch_request
    rv = self.dispatch_request()
  File "/home/uosselab/.local/lib/python3.6/site-packages/flask/app.py", line 1818, in dispatch_request
    return self.view_functions[rule.endpoint](**req.view_args)
  File "/home/uosselab/바탕화면/X_TWICE_AI/server.py", line 53, in predict
    prediction = Image_Prediction(PATH, file)
  File "/home/uosselab/바탕화면/X_TWICE_AI/image_prediction.py", line 19, in __init__
    self.current_vector, self.current_norm = self.GetFeatureVector(image)
  File "/home/uosselab/바탕화면/X_TWICE_AI/image_prediction.py", line 24, in GetFeatureVector
    trans_image = self.transform(image).to(self.cuda)
  File "/home/uosselab/.local/lib/python3.6/site-packages/torchvision/transforms/transforms.py", line 60, in __call__
    img = t(img)
  File "/home/uosselab/.local/lib/python3.6/site-packages/torch/nn/modules/module.py", line 889, in _call_impl
    result = self.forward(*input, **kwargs)
  File "/home/uosselab/.local/lib/python3.6/site-packages/torchvision/transforms/transforms.py", line 273, in forward
    return F.resize(img, self.size, self.interpolation)
  File "/home/uosselab/.local/lib/python3.6/site-packages/torchvision/transforms/functional.py", line 375, in resize
    return F_pil.resize(img, size=size, interpolation=pil_interpolation)
  File "/home/uosselab/.local/lib/python3.6/site-packages/torchvision/transforms/functional_pil.py", line 209, in resize
    raise TypeError('img should be PIL Image. Got {}'.format(type(img)))
TypeError: img should be PIL Image. Got <class 'werkzeug.datastructures.FileStorage'>
[2021-08-24 17:30:55 +0900] [9342] [ERROR] Connection in use: ('0.0.0.0', 8000)
[2021-08-24 17:30:55 +0900] [9342] [ERROR] Retrying in 1 second.
[2021-08-24 17:30:56 +0900] [9342] [ERROR] Connection in use: ('0.0.0.0', 8000)
[2021-08-24 17:30:56 +0900] [9342] [ERROR] Retrying in 1 second.
[2021-08-24 17:30:57 +0900] [9342] [ERROR] Connection in use: ('0.0.0.0', 8000)
[2021-08-24 17:30:57 +0900] [9342] [ERROR] Retrying in 1 second.
[2021-08-24 17:30:58 +0900] [9342] [ERROR] Can't connect to ('0.0.0.0', 8000)
[2021-08-24 17:32:42,500] ERROR in app: Exception on /predict [POST]
Traceback (most recent call last):
  File "/home/uosselab/.local/lib/python3.6/site-packages/flask/app.py", line 2311, in wsgi_app
    response = self.full_dispatch_request()
  File "/home/uosselab/.local/lib/python3.6/site-packages/flask/app.py", line 1834, in full_dispatch_request
    rv = self.handle_user_exception(e)
  File "/home/uosselab/.local/lib/python3.6/site-packages/flask/app.py", line 1737, in handle_user_exception
    reraise(exc_type, exc_value, tb)
  File "/home/uosselab/.local/lib/python3.6/site-packages/flask/_compat.py", line 36, in reraise
    raise value
  File "/home/uosselab/.local/lib/python3.6/site-packages/flask/app.py", line 1832, in full_dispatch_request
    rv = self.dispatch_request()
  File "/home/uosselab/.local/lib/python3.6/site-packages/flask/app.py", line 1818, in dispatch_request
    return self.view_functions[rule.endpoint](**req.view_args)
  File "/home/uosselab/바탕화면/X_TWICE_AI/server.py", line 53, in predict
    prediction = Image_Prediction(PATH, file)
  File "/home/uosselab/바탕화면/X_TWICE_AI/image_prediction.py", line 19, in __init__
    self.current_vector, self.current_norm = self.GetFeatureVector(image)
  File "/home/uosselab/바탕화면/X_TWICE_AI/image_prediction.py", line 24, in GetFeatureVector
    trans_image = self.transform(image).to(self.cuda)
  File "/home/uosselab/.local/lib/python3.6/site-packages/torchvision/transforms/transforms.py", line 60, in __call__
    img = t(img)
  File "/home/uosselab/.local/lib/python3.6/site-packages/torch/nn/modules/module.py", line 889, in _call_impl
    result = self.forward(*input, **kwargs)
  File "/home/uosselab/.local/lib/python3.6/site-packages/torchvision/transforms/transforms.py", line 273, in forward
    return F.resize(img, self.size, self.interpolation)
  File "/home/uosselab/.local/lib/python3.6/site-packages/torchvision/transforms/functional.py", line 375, in resize
    return F_pil.resize(img, size=size, interpolation=pil_interpolation)
  File "/home/uosselab/.local/lib/python3.6/site-packages/torchvision/transforms/functional_pil.py", line 209, in resize
    raise TypeError('img should be PIL Image. Got {}'.format(type(img)))
TypeError: img should be PIL Image. Got <class 'werkzeug.datastructures.FileStorage'>
[2021-08-25 15:36:44,824] ERROR in app: Exception on /predict [POST]
Traceback (most recent call last):
  File "/home/uosselab/.local/lib/python3.6/site-packages/flask/app.py", line 2311, in wsgi_app
    response = self.full_dispatch_request()
  File "/home/uosselab/.local/lib/python3.6/site-packages/flask/app.py", line 1834, in full_dispatch_request
    rv = self.handle_user_exception(e)
  File "/home/uosselab/.local/lib/python3.6/site-packages/flask/app.py", line 1737, in handle_user_exception
    reraise(exc_type, exc_value, tb)
  File "/home/uosselab/.local/lib/python3.6/site-packages/flask/_compat.py", line 36, in reraise
    raise value
  File "/home/uosselab/.local/lib/python3.6/site-packages/flask/app.py", line 1832, in full_dispatch_request
    rv = self.dispatch_request()
  File "/home/uosselab/.local/lib/python3.6/site-packages/flask/app.py", line 1818, in dispatch_request
    return self.view_functions[rule.endpoint](**req.view_args)
  File "/home/uosselab/바탕화면/X_TWICE_AI/server.py", line 53, in predict
    prediction = Image_Prediction(PATH, file)
  File "/home/uosselab/바탕화면/X_TWICE_AI/image_prediction.py", line 19, in __init__
    self.current_vector, self.current_norm = self.GetFeatureVector(image)
  File "/home/uosselab/바탕화면/X_TWICE_AI/image_prediction.py", line 24, in GetFeatureVector
    trans_image = self.transform(image).to(self.cuda)
  File "/home/uosselab/.local/lib/python3.6/site-packages/torchvision/transforms/transforms.py", line 60, in __call__
    img = t(img)
  File "/home/uosselab/.local/lib/python3.6/site-packages/torch/nn/modules/module.py", line 889, in _call_impl
    result = self.forward(*input, **kwargs)
  File "/home/uosselab/.local/lib/python3.6/site-packages/torchvision/transforms/transforms.py", line 273, in forward
    return F.resize(img, self.size, self.interpolation)
  File "/home/uosselab/.local/lib/python3.6/site-packages/torchvision/transforms/functional.py", line 375, in resize
    return F_pil.resize(img, size=size, interpolation=pil_interpolation)
  File "/home/uosselab/.local/lib/python3.6/site-packages/torchvision/transforms/functional_pil.py", line 209, in resize
    raise TypeError('img should be PIL Image. Got {}'.format(type(img)))
TypeError: img should be PIL Image. Got <class 'werkzeug.datastructures.FileStorage'>
[2021-08-25 15:38:11,739] ERROR in app: Exception on /predict [POST]
Traceback (most recent call last):
  File "/home/uosselab/.local/lib/python3.6/site-packages/flask/app.py", line 2311, in wsgi_app
    response = self.full_dispatch_request()
  File "/home/uosselab/.local/lib/python3.6/site-packages/flask/app.py", line 1834, in full_dispatch_request
    rv = self.handle_user_exception(e)
  File "/home/uosselab/.local/lib/python3.6/site-packages/flask/app.py", line 1737, in handle_user_exception
    reraise(exc_type, exc_value, tb)
  File "/home/uosselab/.local/lib/python3.6/site-packages/flask/_compat.py", line 36, in reraise
    raise value
  File "/home/uosselab/.local/lib/python3.6/site-packages/flask/app.py", line 1832, in full_dispatch_request
    rv = self.dispatch_request()
  File "/home/uosselab/.local/lib/python3.6/site-packages/flask/app.py", line 1818, in dispatch_request
    return self.view_functions[rule.endpoint](**req.view_args)
  File "/home/uosselab/바탕화면/X_TWICE_AI/server.py", line 53, in predict
    prediction = Image_Prediction(PATH, file)
  File "/home/uosselab/바탕화면/X_TWICE_AI/image_prediction.py", line 19, in __init__
    self.current_vector, self.current_norm = self.GetFeatureVector(image)
  File "/home/uosselab/바탕화면/X_TWICE_AI/image_prediction.py", line 24, in GetFeatureVector
    trans_image = self.transform(image).to(self.cuda)
  File "/home/uosselab/.local/lib/python3.6/site-packages/torchvision/transforms/transforms.py", line 60, in __call__
    img = t(img)
  File "/home/uosselab/.local/lib/python3.6/site-packages/torch/nn/modules/module.py", line 889, in _call_impl
    result = self.forward(*input, **kwargs)
  File "/home/uosselab/.local/lib/python3.6/site-packages/torchvision/transforms/transforms.py", line 273, in forward
    return F.resize(img, self.size, self.interpolation)
  File "/home/uosselab/.local/lib/python3.6/site-packages/torchvision/transforms/functional.py", line 375, in resize
    return F_pil.resize(img, size=size, interpolation=pil_interpolation)
  File "/home/uosselab/.local/lib/python3.6/site-packages/torchvision/transforms/functional_pil.py", line 209, in resize
    raise TypeError('img should be PIL Image. Got {}'.format(type(img)))
TypeError: img should be PIL Image. Got <class 'werkzeug.datastructures.FileStorage'>
[2021-08-25 15:44:05,135] ERROR in app: Exception on /predict [POST]
Traceback (most recent call last):
  File "/home/uosselab/.local/lib/python3.6/site-packages/flask/app.py", line 2311, in wsgi_app
    response = self.full_dispatch_request()
  File "/home/uosselab/.local/lib/python3.6/site-packages/flask/app.py", line 1834, in full_dispatch_request
    rv = self.handle_user_exception(e)
  File "/home/uosselab/.local/lib/python3.6/site-packages/flask/app.py", line 1737, in handle_user_exception
    reraise(exc_type, exc_value, tb)
  File "/home/uosselab/.local/lib/python3.6/site-packages/flask/_compat.py", line 36, in reraise
    raise value
  File "/home/uosselab/.local/lib/python3.6/site-packages/flask/app.py", line 1832, in full_dispatch_request
    rv = self.dispatch_request()
  File "/home/uosselab/.local/lib/python3.6/site-packages/flask/app.py", line 1818, in dispatch_request
    return self.view_functions[rule.endpoint](**req.view_args)
  File "/home/uosselab/바탕화면/X_TWICE_AI/server.py", line 53, in predict
    #prediction = Image_Prediction(PATH, image_bytes=img_bytes)
  File "/home/uosselab/바탕화면/X_TWICE_AI/image_prediction.py", line 19, in __init__
    self.current_vector, self.current_norm = self.GetFeatureVector(image)
  File "/home/uosselab/바탕화면/X_TWICE_AI/image_prediction.py", line 24, in GetFeatureVector
    trans_image = self.transform(image).to(self.cuda)
  File "/home/uosselab/.local/lib/python3.6/site-packages/torchvision/transforms/transforms.py", line 60, in __call__
    img = t(img)
  File "/home/uosselab/.local/lib/python3.6/site-packages/torch/nn/modules/module.py", line 889, in _call_impl
    result = self.forward(*input, **kwargs)
  File "/home/uosselab/.local/lib/python3.6/site-packages/torchvision/transforms/transforms.py", line 273, in forward
    return F.resize(img, self.size, self.interpolation)
  File "/home/uosselab/.local/lib/python3.6/site-packages/torchvision/transforms/functional.py", line 375, in resize
    return F_pil.resize(img, size=size, interpolation=pil_interpolation)
  File "/home/uosselab/.local/lib/python3.6/site-packages/torchvision/transforms/functional_pil.py", line 209, in resize
    raise TypeError('img should be PIL Image. Got {}'.format(type(img)))
TypeError: img should be PIL Image. Got <class 'werkzeug.datastructures.FileStorage'>
[2021-08-25 16:01:11,638] ERROR in app: Exception on /predict [POST]
Traceback (most recent call last):
  File "/home/uosselab/.local/lib/python3.6/site-packages/flask/app.py", line 2311, in wsgi_app
    response = self.full_dispatch_request()
  File "/home/uosselab/.local/lib/python3.6/site-packages/flask/app.py", line 1834, in full_dispatch_request
    rv = self.handle_user_exception(e)
  File "/home/uosselab/.local/lib/python3.6/site-packages/flask/app.py", line 1737, in handle_user_exception
    reraise(exc_type, exc_value, tb)
  File "/home/uosselab/.local/lib/python3.6/site-packages/flask/_compat.py", line 36, in reraise
    raise value
  File "/home/uosselab/.local/lib/python3.6/site-packages/flask/app.py", line 1832, in full_dispatch_request
    rv = self.dispatch_request()
  File "/home/uosselab/.local/lib/python3.6/site-packages/flask/app.py", line 1818, in dispatch_request
    return self.view_functions[rule.endpoint](**req.view_args)
  File "/home/uosselab/바탕화면/X_TWICE_AI/server.py", line 53, in predict
    #return jsonify({'class_id': class_id, 'class_name': class_name})
  File "/home/uosselab/바탕화면/X_TWICE_AI/image_prediction.py", line 19, in __init__
    self.threshold = 0.8
  File "/home/uosselab/바탕화면/X_TWICE_AI/image_prediction.py", line 24, in GetFeatureVector
  File "/home/uosselab/.local/lib/python3.6/site-packages/torchvision/transforms/transforms.py", line 60, in __call__
    img = t(img)
  File "/home/uosselab/.local/lib/python3.6/site-packages/torch/nn/modules/module.py", line 889, in _call_impl
    result = self.forward(*input, **kwargs)
  File "/home/uosselab/.local/lib/python3.6/site-packages/torchvision/transforms/transforms.py", line 273, in forward
    return F.resize(img, self.size, self.interpolation)
  File "/home/uosselab/.local/lib/python3.6/site-packages/torchvision/transforms/functional.py", line 375, in resize
    return F_pil.resize(img, size=size, interpolation=pil_interpolation)
  File "/home/uosselab/.local/lib/python3.6/site-packages/torchvision/transforms/functional_pil.py", line 209, in resize
    raise TypeError('img should be PIL Image. Got {}'.format(type(img)))
TypeError: img should be PIL Image. Got <class 'werkzeug.datastructures.FileStorage'>
[2021-08-25 16:14:10,538] ERROR in app: Exception on /predict [POST]
Traceback (most recent call last):
  File "/home/uosselab/.local/lib/python3.6/site-packages/flask/app.py", line 2311, in wsgi_app
    response = self.full_dispatch_request()
  File "/home/uosselab/.local/lib/python3.6/site-packages/flask/app.py", line 1834, in full_dispatch_request
    rv = self.handle_user_exception(e)
  File "/home/uosselab/.local/lib/python3.6/site-packages/flask/app.py", line 1737, in handle_user_exception
    reraise(exc_type, exc_value, tb)
  File "/home/uosselab/.local/lib/python3.6/site-packages/flask/_compat.py", line 36, in reraise
    raise value
  File "/home/uosselab/.local/lib/python3.6/site-packages/flask/app.py", line 1832, in full_dispatch_request
    rv = self.dispatch_request()
  File "/home/uosselab/.local/lib/python3.6/site-packages/flask/app.py", line 1818, in dispatch_request
    return self.view_functions[rule.endpoint](**req.view_args)
  File "/home/uosselab/바탕화면/X_TWICE_AI/server.py", line 53, in predict
    #return jsonify({'class_id': class_id, 'class_name': class_name})
  File "/home/uosselab/바탕화면/X_TWICE_AI/image_prediction.py", line 19, in __init__
    ])
  File "/home/uosselab/바탕화면/X_TWICE_AI/image_prediction.py", line 24, in GetFeatureVector
    def GetFeatureVector(self, image):
  File "/home/uosselab/.local/lib/python3.6/site-packages/torchvision/transforms/transforms.py", line 60, in __call__
    img = t(img)
  File "/home/uosselab/.local/lib/python3.6/site-packages/torch/nn/modules/module.py", line 889, in _call_impl
    result = self.forward(*input, **kwargs)
  File "/home/uosselab/.local/lib/python3.6/site-packages/torchvision/transforms/transforms.py", line 273, in forward
    return F.resize(img, self.size, self.interpolation)
  File "/home/uosselab/.local/lib/python3.6/site-packages/torchvision/transforms/functional.py", line 375, in resize
    return F_pil.resize(img, size=size, interpolation=pil_interpolation)
  File "/home/uosselab/.local/lib/python3.6/site-packages/torchvision/transforms/functional_pil.py", line 209, in resize
    raise TypeError('img should be PIL Image. Got {}'.format(type(img)))
TypeError: img should be PIL Image. Got <class 'werkzeug.datastructures.FileStorage'>
[2021-08-25 16:15:26,186] ERROR in app: Exception on /predict [POST]
Traceback (most recent call last):
  File "/home/uosselab/.local/lib/python3.6/site-packages/flask/app.py", line 2311, in wsgi_app
    response = self.full_dispatch_request()
  File "/home/uosselab/.local/lib/python3.6/site-packages/flask/app.py", line 1834, in full_dispatch_request
    rv = self.handle_user_exception(e)
  File "/home/uosselab/.local/lib/python3.6/site-packages/flask/app.py", line 1737, in handle_user_exception
    reraise(exc_type, exc_value, tb)
  File "/home/uosselab/.local/lib/python3.6/site-packages/flask/_compat.py", line 36, in reraise
    raise value
  File "/home/uosselab/.local/lib/python3.6/site-packages/flask/app.py", line 1832, in full_dispatch_request
    rv = self.dispatch_request()
  File "/home/uosselab/.local/lib/python3.6/site-packages/flask/app.py", line 1818, in dispatch_request
    return self.view_functions[rule.endpoint](**req.view_args)
  File "/home/uosselab/바탕화면/X_TWICE_AI/server.py", line 53, in predict
    #return jsonify({'class_id': class_id, 'class_name': class_name})
  File "/home/uosselab/바탕화면/X_TWICE_AI/image_prediction.py", line 19, in __init__
    ])
  File "/home/uosselab/바탕화면/X_TWICE_AI/image_prediction.py", line 24, in GetFeatureVector
    def GetFeatureVector(self, image):
  File "/home/uosselab/.local/lib/python3.6/site-packages/torchvision/transforms/transforms.py", line 60, in __call__
    img = t(img)
  File "/home/uosselab/.local/lib/python3.6/site-packages/torch/nn/modules/module.py", line 889, in _call_impl
    result = self.forward(*input, **kwargs)
  File "/home/uosselab/.local/lib/python3.6/site-packages/torchvision/transforms/transforms.py", line 273, in forward
    return F.resize(img, self.size, self.interpolation)
  File "/home/uosselab/.local/lib/python3.6/site-packages/torchvision/transforms/functional.py", line 375, in resize
    return F_pil.resize(img, size=size, interpolation=pil_interpolation)
  File "/home/uosselab/.local/lib/python3.6/site-packages/torchvision/transforms/functional_pil.py", line 209, in resize
    raise TypeError('img should be PIL Image. Got {}'.format(type(img)))
TypeError: img should be PIL Image. Got <class 'werkzeug.datastructures.FileStorage'>
[2021-08-25 16:15:36,504] ERROR in app: Exception on /predict [POST]
Traceback (most recent call last):
  File "/home/uosselab/.local/lib/python3.6/site-packages/flask/app.py", line 2311, in wsgi_app
    response = self.full_dispatch_request()
  File "/home/uosselab/.local/lib/python3.6/site-packages/flask/app.py", line 1834, in full_dispatch_request
    rv = self.handle_user_exception(e)
  File "/home/uosselab/.local/lib/python3.6/site-packages/flask/app.py", line 1737, in handle_user_exception
    reraise(exc_type, exc_value, tb)
  File "/home/uosselab/.local/lib/python3.6/site-packages/flask/_compat.py", line 36, in reraise
    raise value
  File "/home/uosselab/.local/lib/python3.6/site-packages/flask/app.py", line 1832, in full_dispatch_request
    rv = self.dispatch_request()
  File "/home/uosselab/.local/lib/python3.6/site-packages/flask/app.py", line 1818, in dispatch_request
    return self.view_functions[rule.endpoint](**req.view_args)
  File "/home/uosselab/바탕화면/X_TWICE_AI/server.py", line 53, in predict
    #return jsonify({'class_id': class_id, 'class_name': class_name})
  File "/home/uosselab/바탕화면/X_TWICE_AI/image_prediction.py", line 19, in __init__
    ])
  File "/home/uosselab/바탕화면/X_TWICE_AI/image_prediction.py", line 24, in GetFeatureVector
    def GetFeatureVector(self, image):
  File "/home/uosselab/.local/lib/python3.6/site-packages/torchvision/transforms/transforms.py", line 60, in __call__
    img = t(img)
  File "/home/uosselab/.local/lib/python3.6/site-packages/torch/nn/modules/module.py", line 889, in _call_impl
    result = self.forward(*input, **kwargs)
  File "/home/uosselab/.local/lib/python3.6/site-packages/torchvision/transforms/transforms.py", line 273, in forward
    return F.resize(img, self.size, self.interpolation)
  File "/home/uosselab/.local/lib/python3.6/site-packages/torchvision/transforms/functional.py", line 375, in resize
    return F_pil.resize(img, size=size, interpolation=pil_interpolation)
  File "/home/uosselab/.local/lib/python3.6/site-packages/torchvision/transforms/functional_pil.py", line 209, in resize
    raise TypeError('img should be PIL Image. Got {}'.format(type(img)))
TypeError: img should be PIL Image. Got <class 'werkzeug.datastructures.FileStorage'>
[2021-08-25 16:19:02,256] ERROR in app: Exception on /predict [POST]
Traceback (most recent call last):
  File "/home/uosselab/.local/lib/python3.6/site-packages/flask/app.py", line 2311, in wsgi_app
    response = self.full_dispatch_request()
  File "/home/uosselab/.local/lib/python3.6/site-packages/flask/app.py", line 1834, in full_dispatch_request
    rv = self.handle_user_exception(e)
  File "/home/uosselab/.local/lib/python3.6/site-packages/flask/app.py", line 1737, in handle_user_exception
    reraise(exc_type, exc_value, tb)
  File "/home/uosselab/.local/lib/python3.6/site-packages/flask/_compat.py", line 36, in reraise
    raise value
  File "/home/uosselab/.local/lib/python3.6/site-packages/flask/app.py", line 1832, in full_dispatch_request
    rv = self.dispatch_request()
  File "/home/uosselab/.local/lib/python3.6/site-packages/flask/app.py", line 1818, in dispatch_request
    return self.view_functions[rule.endpoint](**req.view_args)
  File "/home/uosselab/바탕화면/X_TWICE_AI/server.py", line 53, in predict
    #return jsonify({'class_id': class_id, 'class_name': class_name})
  File "/home/uosselab/바탕화면/X_TWICE_AI/image_prediction.py", line 19, in __init__
    ])
  File "/home/uosselab/바탕화면/X_TWICE_AI/image_prediction.py", line 24, in GetFeatureVector
    def GetFeatureVector(self, image):
  File "/home/uosselab/.local/lib/python3.6/site-packages/torchvision/transforms/transforms.py", line 60, in __call__
    img = t(img)
  File "/home/uosselab/.local/lib/python3.6/site-packages/torch/nn/modules/module.py", line 889, in _call_impl
    result = self.forward(*input, **kwargs)
  File "/home/uosselab/.local/lib/python3.6/site-packages/torchvision/transforms/transforms.py", line 273, in forward
    return F.resize(img, self.size, self.interpolation)
  File "/home/uosselab/.local/lib/python3.6/site-packages/torchvision/transforms/functional.py", line 375, in resize
    return F_pil.resize(img, size=size, interpolation=pil_interpolation)
  File "/home/uosselab/.local/lib/python3.6/site-packages/torchvision/transforms/functional_pil.py", line 209, in resize
    raise TypeError('img should be PIL Image. Got {}'.format(type(img)))
TypeError: img should be PIL Image. Got <class 'werkzeug.datastructures.FileStorage'>
[2021-08-25 16:19:30,667] ERROR in app: Exception on /predict [POST]
Traceback (most recent call last):
  File "/home/uosselab/.local/lib/python3.6/site-packages/flask/app.py", line 2311, in wsgi_app
    response = self.full_dispatch_request()
  File "/home/uosselab/.local/lib/python3.6/site-packages/flask/app.py", line 1834, in full_dispatch_request
    rv = self.handle_user_exception(e)
  File "/home/uosselab/.local/lib/python3.6/site-packages/flask/app.py", line 1737, in handle_user_exception
    reraise(exc_type, exc_value, tb)
  File "/home/uosselab/.local/lib/python3.6/site-packages/flask/_compat.py", line 36, in reraise
    raise value
  File "/home/uosselab/.local/lib/python3.6/site-packages/flask/app.py", line 1832, in full_dispatch_request
    rv = self.dispatch_request()
  File "/home/uosselab/.local/lib/python3.6/site-packages/flask/app.py", line 1818, in dispatch_request
    return self.view_functions[rule.endpoint](**req.view_args)
  File "/home/uosselab/바탕화면/X_TWICE_AI/server.py", line 53, in predict
    #return jsonify({'class_id': class_id, 'class_name': class_name})
  File "/home/uosselab/바탕화면/X_TWICE_AI/image_prediction.py", line 19, in __init__
    ])
  File "/home/uosselab/바탕화면/X_TWICE_AI/image_prediction.py", line 24, in GetFeatureVector
    def GetFeatureVector(self, image):
  File "/home/uosselab/.local/lib/python3.6/site-packages/torchvision/transforms/transforms.py", line 60, in __call__
    img = t(img)
  File "/home/uosselab/.local/lib/python3.6/site-packages/torch/nn/modules/module.py", line 889, in _call_impl
    result = self.forward(*input, **kwargs)
  File "/home/uosselab/.local/lib/python3.6/site-packages/torchvision/transforms/transforms.py", line 273, in forward
    return F.resize(img, self.size, self.interpolation)
  File "/home/uosselab/.local/lib/python3.6/site-packages/torchvision/transforms/functional.py", line 375, in resize
    return F_pil.resize(img, size=size, interpolation=pil_interpolation)
  File "/home/uosselab/.local/lib/python3.6/site-packages/torchvision/transforms/functional_pil.py", line 209, in resize
    raise TypeError('img should be PIL Image. Got {}'.format(type(img)))
TypeError: img should be PIL Image. Got <class 'werkzeug.datastructures.FileStorage'>
[2021-08-25 16:19:42,977] ERROR in app: Exception on /predict [POST]
Traceback (most recent call last):
  File "/home/uosselab/.local/lib/python3.6/site-packages/flask/app.py", line 2311, in wsgi_app
    response = self.full_dispatch_request()
  File "/home/uosselab/.local/lib/python3.6/site-packages/flask/app.py", line 1834, in full_dispatch_request
    rv = self.handle_user_exception(e)
  File "/home/uosselab/.local/lib/python3.6/site-packages/flask/app.py", line 1737, in handle_user_exception
    reraise(exc_type, exc_value, tb)
  File "/home/uosselab/.local/lib/python3.6/site-packages/flask/_compat.py", line 36, in reraise
    raise value
  File "/home/uosselab/.local/lib/python3.6/site-packages/flask/app.py", line 1832, in full_dispatch_request
    rv = self.dispatch_request()
  File "/home/uosselab/.local/lib/python3.6/site-packages/flask/app.py", line 1818, in dispatch_request
    return self.view_functions[rule.endpoint](**req.view_args)
  File "/home/uosselab/바탕화면/X_TWICE_AI/server.py", line 53, in predict
    #return jsonify({'class_id': class_id, 'class_name': class_name})
  File "/home/uosselab/바탕화면/X_TWICE_AI/image_prediction.py", line 19, in __init__
    ])
  File "/home/uosselab/바탕화면/X_TWICE_AI/image_prediction.py", line 24, in GetFeatureVector
    def GetFeatureVector(self, image):
  File "/home/uosselab/.local/lib/python3.6/site-packages/torchvision/transforms/transforms.py", line 60, in __call__
    img = t(img)
  File "/home/uosselab/.local/lib/python3.6/site-packages/torch/nn/modules/module.py", line 889, in _call_impl
    result = self.forward(*input, **kwargs)
  File "/home/uosselab/.local/lib/python3.6/site-packages/torchvision/transforms/transforms.py", line 273, in forward
    return F.resize(img, self.size, self.interpolation)
  File "/home/uosselab/.local/lib/python3.6/site-packages/torchvision/transforms/functional.py", line 375, in resize
    return F_pil.resize(img, size=size, interpolation=pil_interpolation)
  File "/home/uosselab/.local/lib/python3.6/site-packages/torchvision/transforms/functional_pil.py", line 209, in resize
    raise TypeError('img should be PIL Image. Got {}'.format(type(img)))
TypeError: img should be PIL Image. Got <class 'werkzeug.datastructures.FileStorage'>
[2021-08-25 16:20:18,544] ERROR in app: Exception on /predict [POST]
Traceback (most recent call last):
  File "/home/uosselab/.local/lib/python3.6/site-packages/flask/app.py", line 2311, in wsgi_app
    response = self.full_dispatch_request()
  File "/home/uosselab/.local/lib/python3.6/site-packages/flask/app.py", line 1834, in full_dispatch_request
    rv = self.handle_user_exception(e)
  File "/home/uosselab/.local/lib/python3.6/site-packages/flask/app.py", line 1737, in handle_user_exception
    reraise(exc_type, exc_value, tb)
  File "/home/uosselab/.local/lib/python3.6/site-packages/flask/_compat.py", line 36, in reraise
    raise value
  File "/home/uosselab/.local/lib/python3.6/site-packages/flask/app.py", line 1832, in full_dispatch_request
    rv = self.dispatch_request()
  File "/home/uosselab/.local/lib/python3.6/site-packages/flask/app.py", line 1818, in dispatch_request
    return self.view_functions[rule.endpoint](**req.view_args)
  File "/home/uosselab/바탕화면/X_TWICE_AI/server.py", line 53, in predict
    #return jsonify({'class_id': class_id, 'class_name': class_name})
  File "/home/uosselab/바탕화면/X_TWICE_AI/image_prediction.py", line 19, in __init__
    ])
  File "/home/uosselab/바탕화면/X_TWICE_AI/image_prediction.py", line 24, in GetFeatureVector
    def GetFeatureVector(self, image):
  File "/home/uosselab/.local/lib/python3.6/site-packages/torchvision/transforms/transforms.py", line 60, in __call__
    img = t(img)
  File "/home/uosselab/.local/lib/python3.6/site-packages/torch/nn/modules/module.py", line 889, in _call_impl
    result = self.forward(*input, **kwargs)
  File "/home/uosselab/.local/lib/python3.6/site-packages/torchvision/transforms/transforms.py", line 273, in forward
    return F.resize(img, self.size, self.interpolation)
  File "/home/uosselab/.local/lib/python3.6/site-packages/torchvision/transforms/functional.py", line 375, in resize
    return F_pil.resize(img, size=size, interpolation=pil_interpolation)
  File "/home/uosselab/.local/lib/python3.6/site-packages/torchvision/transforms/functional_pil.py", line 209, in resize
    raise TypeError('img should be PIL Image. Got {}'.format(type(img)))
TypeError: img should be PIL Image. Got <class 'werkzeug.datastructures.FileStorage'>
[2021-08-25 16:20:24,030] ERROR in app: Exception on /predict [POST]
Traceback (most recent call last):
  File "/home/uosselab/.local/lib/python3.6/site-packages/flask/app.py", line 2311, in wsgi_app
    response = self.full_dispatch_request()
  File "/home/uosselab/.local/lib/python3.6/site-packages/flask/app.py", line 1834, in full_dispatch_request
    rv = self.handle_user_exception(e)
  File "/home/uosselab/.local/lib/python3.6/site-packages/flask/app.py", line 1737, in handle_user_exception
    reraise(exc_type, exc_value, tb)
  File "/home/uosselab/.local/lib/python3.6/site-packages/flask/_compat.py", line 36, in reraise
    raise value
  File "/home/uosselab/.local/lib/python3.6/site-packages/flask/app.py", line 1832, in full_dispatch_request
    rv = self.dispatch_request()
  File "/home/uosselab/.local/lib/python3.6/site-packages/flask/app.py", line 1818, in dispatch_request
    return self.view_functions[rule.endpoint](**req.view_args)
  File "/home/uosselab/바탕화면/X_TWICE_AI/server.py", line 53, in predict
    #return jsonify({'class_id': class_id, 'class_name': class_name})
  File "/home/uosselab/바탕화면/X_TWICE_AI/image_prediction.py", line 19, in __init__
    ])
  File "/home/uosselab/바탕화면/X_TWICE_AI/image_prediction.py", line 24, in GetFeatureVector
    def GetFeatureVector(self, image):
  File "/home/uosselab/.local/lib/python3.6/site-packages/torchvision/transforms/transforms.py", line 60, in __call__
    img = t(img)
  File "/home/uosselab/.local/lib/python3.6/site-packages/torch/nn/modules/module.py", line 889, in _call_impl
    result = self.forward(*input, **kwargs)
  File "/home/uosselab/.local/lib/python3.6/site-packages/torchvision/transforms/transforms.py", line 273, in forward
    return F.resize(img, self.size, self.interpolation)
  File "/home/uosselab/.local/lib/python3.6/site-packages/torchvision/transforms/functional.py", line 375, in resize
    return F_pil.resize(img, size=size, interpolation=pil_interpolation)
  File "/home/uosselab/.local/lib/python3.6/site-packages/torchvision/transforms/functional_pil.py", line 209, in resize
    raise TypeError('img should be PIL Image. Got {}'.format(type(img)))
TypeError: img should be PIL Image. Got <class 'werkzeug.datastructures.FileStorage'>
[2021-08-25 16:21:07 +0900] [8920] [INFO] Handling signal: term
[2021-08-25 16:21:07 +0900] [9286] [INFO] Worker exiting (pid: 9286)
[2021-08-25 16:21:07 +0900] [8920] [INFO] Shutting down: Master
[2021-08-25 16:21:12 +0900] [20436] [INFO] Starting gunicorn 20.1.0
[2021-08-25 16:21:12 +0900] [20436] [INFO] Listening at: http://0.0.0.0:8000 (20436)
[2021-08-25 16:21:12 +0900] [20436] [INFO] Using worker: sync
[2021-08-25 16:21:12 +0900] [20439] [INFO] Booting worker with pid: 20439
[2021-08-25 16:21:18,362] ERROR in app: Exception on /predict [POST]
Traceback (most recent call last):
  File "/home/uosselab/.local/lib/python3.6/site-packages/flask/app.py", line 2311, in wsgi_app
    response = self.full_dispatch_request()
  File "/home/uosselab/.local/lib/python3.6/site-packages/flask/app.py", line 1834, in full_dispatch_request
    rv = self.handle_user_exception(e)
  File "/home/uosselab/.local/lib/python3.6/site-packages/flask/app.py", line 1737, in handle_user_exception
    reraise(exc_type, exc_value, tb)
  File "/home/uosselab/.local/lib/python3.6/site-packages/flask/_compat.py", line 36, in reraise
    raise value
  File "/home/uosselab/.local/lib/python3.6/site-packages/flask/app.py", line 1832, in full_dispatch_request
    rv = self.dispatch_request()
  File "/home/uosselab/.local/lib/python3.6/site-packages/flask/app.py", line 1818, in dispatch_request
    return self.view_functions[rule.endpoint](**req.view_args)
  File "/home/uosselab/바탕화면/X_TWICE_AI/server.py", line 55, in predict
    prediction = Image_Prediction(PATH, file)
  File "/home/uosselab/바탕화면/X_TWICE_AI/image_prediction.py", line 21, in __init__
    self.current_vector, self.current_norm = self.GetFeatureVector(image)
  File "/home/uosselab/바탕화면/X_TWICE_AI/image_prediction.py", line 26, in GetFeatureVector
    trans_image = self.transform(image).to(self.cuda)
  File "/home/uosselab/.local/lib/python3.6/site-packages/torchvision/transforms/transforms.py", line 60, in __call__
    img = t(img)
  File "/home/uosselab/.local/lib/python3.6/site-packages/torch/nn/modules/module.py", line 889, in _call_impl
    result = self.forward(*input, **kwargs)
  File "/home/uosselab/.local/lib/python3.6/site-packages/torchvision/transforms/transforms.py", line 273, in forward
    return F.resize(img, self.size, self.interpolation)
  File "/home/uosselab/.local/lib/python3.6/site-packages/torchvision/transforms/functional.py", line 375, in resize
    return F_pil.resize(img, size=size, interpolation=pil_interpolation)
  File "/home/uosselab/.local/lib/python3.6/site-packages/torchvision/transforms/functional_pil.py", line 209, in resize
    raise TypeError('img should be PIL Image. Got {}'.format(type(img)))
TypeError: img should be PIL Image. Got <class 'werkzeug.datastructures.FileStorage'>
[2021-08-25 16:24:28,306] ERROR in app: Exception on /predict [POST]
Traceback (most recent call last):
  File "/home/uosselab/.local/lib/python3.6/site-packages/flask/app.py", line 2311, in wsgi_app
    response = self.full_dispatch_request()
  File "/home/uosselab/.local/lib/python3.6/site-packages/flask/app.py", line 1834, in full_dispatch_request
    rv = self.handle_user_exception(e)
  File "/home/uosselab/.local/lib/python3.6/site-packages/flask/app.py", line 1737, in handle_user_exception
    reraise(exc_type, exc_value, tb)
  File "/home/uosselab/.local/lib/python3.6/site-packages/flask/_compat.py", line 36, in reraise
    raise value
  File "/home/uosselab/.local/lib/python3.6/site-packages/flask/app.py", line 1832, in full_dispatch_request
    rv = self.dispatch_request()
  File "/home/uosselab/.local/lib/python3.6/site-packages/flask/app.py", line 1818, in dispatch_request
    return self.view_functions[rule.endpoint](**req.view_args)
  File "/home/uosselab/바탕화면/X_TWICE_AI/server.py", line 55, in predict
    prediction = Image_Prediction(PATH, file)
  File "/home/uosselab/바탕화면/X_TWICE_AI/image_prediction.py", line 21, in __init__
    self.current_vector, self.current_norm = self.GetFeatureVector(image)
  File "/home/uosselab/바탕화면/X_TWICE_AI/image_prediction.py", line 26, in GetFeatureVector
    trans_image = self.transform(image).to(self.cuda)
  File "/home/uosselab/.local/lib/python3.6/site-packages/torchvision/transforms/transforms.py", line 60, in __call__
    img = t(img)
  File "/home/uosselab/.local/lib/python3.6/site-packages/torch/nn/modules/module.py", line 889, in _call_impl
    result = self.forward(*input, **kwargs)
  File "/home/uosselab/.local/lib/python3.6/site-packages/torchvision/transforms/transforms.py", line 273, in forward
    return F.resize(img, self.size, self.interpolation)
  File "/home/uosselab/.local/lib/python3.6/site-packages/torchvision/transforms/functional.py", line 375, in resize
    return F_pil.resize(img, size=size, interpolation=pil_interpolation)
  File "/home/uosselab/.local/lib/python3.6/site-packages/torchvision/transforms/functional_pil.py", line 209, in resize
    raise TypeError('img should be PIL Image. Got {}'.format(type(img)))
TypeError: img should be PIL Image. Got <class 'werkzeug.datastructures.FileStorage'>
[2021-08-25 16:24:57,436] ERROR in app: Exception on /predict [POST]
Traceback (most recent call last):
  File "/home/uosselab/.local/lib/python3.6/site-packages/flask/app.py", line 2311, in wsgi_app
    response = self.full_dispatch_request()
  File "/home/uosselab/.local/lib/python3.6/site-packages/flask/app.py", line 1834, in full_dispatch_request
    rv = self.handle_user_exception(e)
  File "/home/uosselab/.local/lib/python3.6/site-packages/flask/app.py", line 1737, in handle_user_exception
    reraise(exc_type, exc_value, tb)
  File "/home/uosselab/.local/lib/python3.6/site-packages/flask/_compat.py", line 36, in reraise
    raise value
  File "/home/uosselab/.local/lib/python3.6/site-packages/flask/app.py", line 1832, in full_dispatch_request
    rv = self.dispatch_request()
  File "/home/uosselab/.local/lib/python3.6/site-packages/flask/app.py", line 1818, in dispatch_request
    return self.view_functions[rule.endpoint](**req.view_args)
  File "/home/uosselab/바탕화면/X_TWICE_AI/server.py", line 55, in predict
    prediction = Image_Prediction(PATH, file)
  File "/home/uosselab/바탕화면/X_TWICE_AI/image_prediction.py", line 21, in __init__
    self.current_vector, self.current_norm = self.GetFeatureVector(image)
  File "/home/uosselab/바탕화면/X_TWICE_AI/image_prediction.py", line 26, in GetFeatureVector
    trans_image = self.transform(image).to(self.cuda)
  File "/home/uosselab/.local/lib/python3.6/site-packages/torchvision/transforms/transforms.py", line 60, in __call__
    img = t(img)
  File "/home/uosselab/.local/lib/python3.6/site-packages/torch/nn/modules/module.py", line 889, in _call_impl
    result = self.forward(*input, **kwargs)
  File "/home/uosselab/.local/lib/python3.6/site-packages/torchvision/transforms/transforms.py", line 273, in forward
    return F.resize(img, self.size, self.interpolation)
  File "/home/uosselab/.local/lib/python3.6/site-packages/torchvision/transforms/functional.py", line 375, in resize
    return F_pil.resize(img, size=size, interpolation=pil_interpolation)
  File "/home/uosselab/.local/lib/python3.6/site-packages/torchvision/transforms/functional_pil.py", line 209, in resize
    raise TypeError('img should be PIL Image. Got {}'.format(type(img)))
TypeError: img should be PIL Image. Got <class 'werkzeug.datastructures.FileStorage'>
[2021-08-25 16:26:29,446] ERROR in app: Exception on /predict [POST]
Traceback (most recent call last):
  File "/home/uosselab/.local/lib/python3.6/site-packages/flask/app.py", line 2311, in wsgi_app
    response = self.full_dispatch_request()
  File "/home/uosselab/.local/lib/python3.6/site-packages/flask/app.py", line 1834, in full_dispatch_request
    rv = self.handle_user_exception(e)
  File "/home/uosselab/.local/lib/python3.6/site-packages/flask/app.py", line 1737, in handle_user_exception
    reraise(exc_type, exc_value, tb)
  File "/home/uosselab/.local/lib/python3.6/site-packages/flask/_compat.py", line 36, in reraise
    raise value
  File "/home/uosselab/.local/lib/python3.6/site-packages/flask/app.py", line 1832, in full_dispatch_request
    rv = self.dispatch_request()
  File "/home/uosselab/.local/lib/python3.6/site-packages/flask/app.py", line 1818, in dispatch_request
    return self.view_functions[rule.endpoint](**req.view_args)
  File "/home/uosselab/바탕화면/X_TWICE_AI/server.py", line 55, in predict
    prediction = Image_Prediction(PATH, file)
  File "/home/uosselab/바탕화면/X_TWICE_AI/image_prediction.py", line 21, in __init__
    self.current_vector, self.current_norm = self.GetFeatureVector(image)
  File "/home/uosselab/바탕화면/X_TWICE_AI/image_prediction.py", line 26, in GetFeatureVector
    trans_image = self.transform(image).to(self.cuda)
  File "/home/uosselab/.local/lib/python3.6/site-packages/torchvision/transforms/transforms.py", line 60, in __call__
    img = t(img)
  File "/home/uosselab/.local/lib/python3.6/site-packages/torch/nn/modules/module.py", line 889, in _call_impl
    result = self.forward(*input, **kwargs)
  File "/home/uosselab/.local/lib/python3.6/site-packages/torchvision/transforms/transforms.py", line 273, in forward
    return F.resize(img, self.size, self.interpolation)
  File "/home/uosselab/.local/lib/python3.6/site-packages/torchvision/transforms/functional.py", line 375, in resize
    return F_pil.resize(img, size=size, interpolation=pil_interpolation)
  File "/home/uosselab/.local/lib/python3.6/site-packages/torchvision/transforms/functional_pil.py", line 209, in resize
    raise TypeError('img should be PIL Image. Got {}'.format(type(img)))
TypeError: img should be PIL Image. Got <class 'werkzeug.datastructures.FileStorage'>
[2021-08-25 16:27:14,264] ERROR in app: Exception on /predict [POST]
Traceback (most recent call last):
  File "/home/uosselab/.local/lib/python3.6/site-packages/flask/app.py", line 2311, in wsgi_app
    response = self.full_dispatch_request()
  File "/home/uosselab/.local/lib/python3.6/site-packages/flask/app.py", line 1834, in full_dispatch_request
    rv = self.handle_user_exception(e)
  File "/home/uosselab/.local/lib/python3.6/site-packages/flask/app.py", line 1737, in handle_user_exception
    reraise(exc_type, exc_value, tb)
  File "/home/uosselab/.local/lib/python3.6/site-packages/flask/_compat.py", line 36, in reraise
    raise value
  File "/home/uosselab/.local/lib/python3.6/site-packages/flask/app.py", line 1832, in full_dispatch_request
    rv = self.dispatch_request()
  File "/home/uosselab/.local/lib/python3.6/site-packages/flask/app.py", line 1818, in dispatch_request
    return self.view_functions[rule.endpoint](**req.view_args)
  File "/home/uosselab/바탕화면/X_TWICE_AI/server.py", line 55, in predict
    prediction = Image_Prediction(PATH, file)
  File "/home/uosselab/바탕화면/X_TWICE_AI/image_prediction.py", line 21, in __init__
    self.current_vector, self.current_norm = self.GetFeatureVector(image)
  File "/home/uosselab/바탕화면/X_TWICE_AI/image_prediction.py", line 26, in GetFeatureVector
    trans_image = self.transform(image).to(self.cuda)
  File "/home/uosselab/.local/lib/python3.6/site-packages/torchvision/transforms/transforms.py", line 60, in __call__
    img = t(img)
  File "/home/uosselab/.local/lib/python3.6/site-packages/torch/nn/modules/module.py", line 889, in _call_impl
    result = self.forward(*input, **kwargs)
  File "/home/uosselab/.local/lib/python3.6/site-packages/torchvision/transforms/transforms.py", line 273, in forward
    return F.resize(img, self.size, self.interpolation)
  File "/home/uosselab/.local/lib/python3.6/site-packages/torchvision/transforms/functional.py", line 375, in resize
    return F_pil.resize(img, size=size, interpolation=pil_interpolation)
  File "/home/uosselab/.local/lib/python3.6/site-packages/torchvision/transforms/functional_pil.py", line 209, in resize
    raise TypeError('img should be PIL Image. Got {}'.format(type(img)))
TypeError: img should be PIL Image. Got <class 'werkzeug.datastructures.FileStorage'>
[2021-08-25 16:27:18,822] ERROR in app: Exception on /predict [POST]
Traceback (most recent call last):
  File "/home/uosselab/.local/lib/python3.6/site-packages/flask/app.py", line 2311, in wsgi_app
    response = self.full_dispatch_request()
  File "/home/uosselab/.local/lib/python3.6/site-packages/flask/app.py", line 1834, in full_dispatch_request
    rv = self.handle_user_exception(e)
  File "/home/uosselab/.local/lib/python3.6/site-packages/flask/app.py", line 1737, in handle_user_exception
    reraise(exc_type, exc_value, tb)
  File "/home/uosselab/.local/lib/python3.6/site-packages/flask/_compat.py", line 36, in reraise
    raise value
  File "/home/uosselab/.local/lib/python3.6/site-packages/flask/app.py", line 1832, in full_dispatch_request
    rv = self.dispatch_request()
  File "/home/uosselab/.local/lib/python3.6/site-packages/flask/app.py", line 1818, in dispatch_request
    return self.view_functions[rule.endpoint](**req.view_args)
  File "/home/uosselab/바탕화면/X_TWICE_AI/server.py", line 55, in predict
    prediction = Image_Prediction(PATH, file)
  File "/home/uosselab/바탕화면/X_TWICE_AI/image_prediction.py", line 21, in __init__
    self.current_vector, self.current_norm = self.GetFeatureVector(image)
  File "/home/uosselab/바탕화면/X_TWICE_AI/image_prediction.py", line 26, in GetFeatureVector
    trans_image = self.transform(image).to(self.cuda)
  File "/home/uosselab/.local/lib/python3.6/site-packages/torchvision/transforms/transforms.py", line 60, in __call__
    img = t(img)
  File "/home/uosselab/.local/lib/python3.6/site-packages/torch/nn/modules/module.py", line 889, in _call_impl
    result = self.forward(*input, **kwargs)
  File "/home/uosselab/.local/lib/python3.6/site-packages/torchvision/transforms/transforms.py", line 273, in forward
    return F.resize(img, self.size, self.interpolation)
  File "/home/uosselab/.local/lib/python3.6/site-packages/torchvision/transforms/functional.py", line 375, in resize
    return F_pil.resize(img, size=size, interpolation=pil_interpolation)
  File "/home/uosselab/.local/lib/python3.6/site-packages/torchvision/transforms/functional_pil.py", line 209, in resize
    raise TypeError('img should be PIL Image. Got {}'.format(type(img)))
TypeError: img should be PIL Image. Got <class 'werkzeug.datastructures.FileStorage'>
[2021-08-25 16:27:34 +0900] [20611] [INFO] Starting gunicorn 20.1.0
[2021-08-25 16:27:34 +0900] [20611] [ERROR] Connection in use: ('0.0.0.0', 8000)
[2021-08-25 16:27:34 +0900] [20611] [ERROR] Retrying in 1 second.
[2021-08-25 16:27:35 +0900] [20611] [ERROR] Connection in use: ('0.0.0.0', 8000)
[2021-08-25 16:27:35 +0900] [20611] [ERROR] Retrying in 1 second.
[2021-08-25 16:27:36 +0900] [20611] [ERROR] Connection in use: ('0.0.0.0', 8000)
[2021-08-25 16:27:36 +0900] [20611] [ERROR] Retrying in 1 second.
[2021-08-25 16:27:36,558] ERROR in app: Exception on /predict [POST]
Traceback (most recent call last):
  File "/home/uosselab/.local/lib/python3.6/site-packages/flask/app.py", line 2311, in wsgi_app
    response = self.full_dispatch_request()
  File "/home/uosselab/.local/lib/python3.6/site-packages/flask/app.py", line 1834, in full_dispatch_request
    rv = self.handle_user_exception(e)
  File "/home/uosselab/.local/lib/python3.6/site-packages/flask/app.py", line 1737, in handle_user_exception
    reraise(exc_type, exc_value, tb)
  File "/home/uosselab/.local/lib/python3.6/site-packages/flask/_compat.py", line 36, in reraise
    raise value
  File "/home/uosselab/.local/lib/python3.6/site-packages/flask/app.py", line 1832, in full_dispatch_request
    rv = self.dispatch_request()
  File "/home/uosselab/.local/lib/python3.6/site-packages/flask/app.py", line 1818, in dispatch_request
    return self.view_functions[rule.endpoint](**req.view_args)
  File "/home/uosselab/바탕화면/X_TWICE_AI/server.py", line 55, in predict
    prediction = Image_Prediction(PATH, file)
  File "/home/uosselab/바탕화면/X_TWICE_AI/image_prediction.py", line 21, in __init__
    self.current_vector, self.current_norm = self.GetFeatureVector(image)
  File "/home/uosselab/바탕화면/X_TWICE_AI/image_prediction.py", line 26, in GetFeatureVector
    trans_image = self.transform(image).to(self.cuda)
  File "/home/uosselab/.local/lib/python3.6/site-packages/torchvision/transforms/transforms.py", line 60, in __call__
    img = t(img)
  File "/home/uosselab/.local/lib/python3.6/site-packages/torch/nn/modules/module.py", line 889, in _call_impl
    result = self.forward(*input, **kwargs)
  File "/home/uosselab/.local/lib/python3.6/site-packages/torchvision/transforms/transforms.py", line 273, in forward
    return F.resize(img, self.size, self.interpolation)
  File "/home/uosselab/.local/lib/python3.6/site-packages/torchvision/transforms/functional.py", line 375, in resize
    return F_pil.resize(img, size=size, interpolation=pil_interpolation)
  File "/home/uosselab/.local/lib/python3.6/site-packages/torchvision/transforms/functional_pil.py", line 209, in resize
    raise TypeError('img should be PIL Image. Got {}'.format(type(img)))
TypeError: img should be PIL Image. Got <class 'werkzeug.datastructures.FileStorage'>
[2021-08-25 16:27:37 +0900] [20611] [ERROR] Connection in use: ('0.0.0.0', 8000)
[2021-08-25 16:27:37 +0900] [20611] [ERROR] Retrying in 1 second.
[2021-08-25 16:27:38 +0900] [20611] [ERROR] Connection in use: ('0.0.0.0', 8000)
[2021-08-25 16:27:38 +0900] [20611] [ERROR] Retrying in 1 second.
[2021-08-25 16:27:39 +0900] [20611] [ERROR] Can't connect to ('0.0.0.0', 8000)
[2021-08-25 16:28:20,654] ERROR in app: Exception on /predict [POST]
Traceback (most recent call last):
  File "/home/uosselab/.local/lib/python3.6/site-packages/flask/app.py", line 2311, in wsgi_app
    response = self.full_dispatch_request()
  File "/home/uosselab/.local/lib/python3.6/site-packages/flask/app.py", line 1834, in full_dispatch_request
    rv = self.handle_user_exception(e)
  File "/home/uosselab/.local/lib/python3.6/site-packages/flask/app.py", line 1737, in handle_user_exception
    reraise(exc_type, exc_value, tb)
  File "/home/uosselab/.local/lib/python3.6/site-packages/flask/_compat.py", line 36, in reraise
    raise value
  File "/home/uosselab/.local/lib/python3.6/site-packages/flask/app.py", line 1832, in full_dispatch_request
    rv = self.dispatch_request()
  File "/home/uosselab/.local/lib/python3.6/site-packages/flask/app.py", line 1818, in dispatch_request
    return self.view_functions[rule.endpoint](**req.view_args)
  File "/home/uosselab/바탕화면/X_TWICE_AI/server.py", line 55, in predict
    prediction = Image_Prediction(PATH, file)
  File "/home/uosselab/바탕화면/X_TWICE_AI/image_prediction.py", line 21, in __init__
    self.current_vector, self.current_norm = self.GetFeatureVector(image)
  File "/home/uosselab/바탕화면/X_TWICE_AI/image_prediction.py", line 26, in GetFeatureVector
    trans_image = self.transform(image).to(self.cuda)
  File "/home/uosselab/.local/lib/python3.6/site-packages/torchvision/transforms/transforms.py", line 60, in __call__
    img = t(img)
  File "/home/uosselab/.local/lib/python3.6/site-packages/torch/nn/modules/module.py", line 889, in _call_impl
    result = self.forward(*input, **kwargs)
  File "/home/uosselab/.local/lib/python3.6/site-packages/torchvision/transforms/transforms.py", line 273, in forward
    return F.resize(img, self.size, self.interpolation)
  File "/home/uosselab/.local/lib/python3.6/site-packages/torchvision/transforms/functional.py", line 375, in resize
    return F_pil.resize(img, size=size, interpolation=pil_interpolation)
  File "/home/uosselab/.local/lib/python3.6/site-packages/torchvision/transforms/functional_pil.py", line 209, in resize
    raise TypeError('img should be PIL Image. Got {}'.format(type(img)))
TypeError: img should be PIL Image. Got <class 'werkzeug.datastructures.FileStorage'>
[2021-08-25 16:29:16,086] ERROR in app: Exception on /predict [POST]
Traceback (most recent call last):
  File "/home/uosselab/.local/lib/python3.6/site-packages/flask/app.py", line 2311, in wsgi_app
    response = self.full_dispatch_request()
  File "/home/uosselab/.local/lib/python3.6/site-packages/flask/app.py", line 1834, in full_dispatch_request
    rv = self.handle_user_exception(e)
  File "/home/uosselab/.local/lib/python3.6/site-packages/flask/app.py", line 1737, in handle_user_exception
    reraise(exc_type, exc_value, tb)
  File "/home/uosselab/.local/lib/python3.6/site-packages/flask/_compat.py", line 36, in reraise
    raise value
  File "/home/uosselab/.local/lib/python3.6/site-packages/flask/app.py", line 1832, in full_dispatch_request
    rv = self.dispatch_request()
  File "/home/uosselab/.local/lib/python3.6/site-packages/flask/app.py", line 1818, in dispatch_request
    return self.view_functions[rule.endpoint](**req.view_args)
  File "/home/uosselab/바탕화면/X_TWICE_AI/server.py", line 55, in predict
    prediction = Image_Prediction(PATH, file)
  File "/home/uosselab/바탕화면/X_TWICE_AI/image_prediction.py", line 21, in __init__
    self.current_vector, self.current_norm = self.GetFeatureVector(image)
  File "/home/uosselab/바탕화면/X_TWICE_AI/image_prediction.py", line 26, in GetFeatureVector
    trans_image = self.transform(image).to(self.cuda)
  File "/home/uosselab/.local/lib/python3.6/site-packages/torchvision/transforms/transforms.py", line 60, in __call__
    img = t(img)
  File "/home/uosselab/.local/lib/python3.6/site-packages/torch/nn/modules/module.py", line 889, in _call_impl
    result = self.forward(*input, **kwargs)
  File "/home/uosselab/.local/lib/python3.6/site-packages/torchvision/transforms/transforms.py", line 273, in forward
    return F.resize(img, self.size, self.interpolation)
  File "/home/uosselab/.local/lib/python3.6/site-packages/torchvision/transforms/functional.py", line 375, in resize
    return F_pil.resize(img, size=size, interpolation=pil_interpolation)
  File "/home/uosselab/.local/lib/python3.6/site-packages/torchvision/transforms/functional_pil.py", line 209, in resize
    raise TypeError('img should be PIL Image. Got {}'.format(type(img)))
TypeError: img should be PIL Image. Got <class 'werkzeug.datastructures.FileStorage'>
[2021-08-25 16:30:22,814] ERROR in app: Exception on /predict [POST]
Traceback (most recent call last):
  File "/home/uosselab/.local/lib/python3.6/site-packages/flask/app.py", line 2311, in wsgi_app
    response = self.full_dispatch_request()
  File "/home/uosselab/.local/lib/python3.6/site-packages/flask/app.py", line 1834, in full_dispatch_request
    rv = self.handle_user_exception(e)
  File "/home/uosselab/.local/lib/python3.6/site-packages/flask/app.py", line 1737, in handle_user_exception
    reraise(exc_type, exc_value, tb)
  File "/home/uosselab/.local/lib/python3.6/site-packages/flask/_compat.py", line 36, in reraise
    raise value
  File "/home/uosselab/.local/lib/python3.6/site-packages/flask/app.py", line 1832, in full_dispatch_request
    rv = self.dispatch_request()
  File "/home/uosselab/.local/lib/python3.6/site-packages/flask/app.py", line 1818, in dispatch_request
    return self.view_functions[rule.endpoint](**req.view_args)
  File "/home/uosselab/바탕화면/X_TWICE_AI/server.py", line 55, in predict
    '''
  File "/home/uosselab/바탕화면/X_TWICE_AI/image_prediction.py", line 21, in __init__
    self.current_vector, self.current_norm = self.GetFeatureVector(image)
  File "/home/uosselab/바탕화면/X_TWICE_AI/image_prediction.py", line 26, in GetFeatureVector
    trans_image = self.transform(image).to(self.cuda)
  File "/home/uosselab/.local/lib/python3.6/site-packages/torchvision/transforms/transforms.py", line 60, in __call__
    img = t(img)
  File "/home/uosselab/.local/lib/python3.6/site-packages/torch/nn/modules/module.py", line 889, in _call_impl
    result = self.forward(*input, **kwargs)
  File "/home/uosselab/.local/lib/python3.6/site-packages/torchvision/transforms/transforms.py", line 273, in forward
    return F.resize(img, self.size, self.interpolation)
  File "/home/uosselab/.local/lib/python3.6/site-packages/torchvision/transforms/functional.py", line 375, in resize
    return F_pil.resize(img, size=size, interpolation=pil_interpolation)
  File "/home/uosselab/.local/lib/python3.6/site-packages/torchvision/transforms/functional_pil.py", line 209, in resize
    raise TypeError('img should be PIL Image. Got {}'.format(type(img)))
TypeError: img should be PIL Image. Got <class 'werkzeug.datastructures.FileStorage'>
[2021-08-25 16:30:36 +0900] [20702] [INFO] Starting gunicorn 20.1.0
[2021-08-25 16:30:36 +0900] [20702] [ERROR] Connection in use: ('0.0.0.0', 8000)
[2021-08-25 16:30:36 +0900] [20702] [ERROR] Retrying in 1 second.
[2021-08-25 16:30:37 +0900] [20702] [ERROR] Connection in use: ('0.0.0.0', 8000)
[2021-08-25 16:30:37 +0900] [20702] [ERROR] Retrying in 1 second.
[2021-08-25 16:30:38 +0900] [20702] [ERROR] Connection in use: ('0.0.0.0', 8000)
[2021-08-25 16:30:38 +0900] [20702] [ERROR] Retrying in 1 second.
[2021-08-25 16:30:39,310] ERROR in app: Exception on /predict [POST]
Traceback (most recent call last):
  File "/home/uosselab/.local/lib/python3.6/site-packages/flask/app.py", line 2311, in wsgi_app
    response = self.full_dispatch_request()
  File "/home/uosselab/.local/lib/python3.6/site-packages/flask/app.py", line 1834, in full_dispatch_request
    rv = self.handle_user_exception(e)
  File "/home/uosselab/.local/lib/python3.6/site-packages/flask/app.py", line 1737, in handle_user_exception
    reraise(exc_type, exc_value, tb)
  File "/home/uosselab/.local/lib/python3.6/site-packages/flask/_compat.py", line 36, in reraise
    raise value
  File "/home/uosselab/.local/lib/python3.6/site-packages/flask/app.py", line 1832, in full_dispatch_request
    rv = self.dispatch_request()
  File "/home/uosselab/.local/lib/python3.6/site-packages/flask/app.py", line 1818, in dispatch_request
    return self.view_functions[rule.endpoint](**req.view_args)
  File "/home/uosselab/바탕화면/X_TWICE_AI/server.py", line 55, in predict
    '''
  File "/home/uosselab/바탕화면/X_TWICE_AI/image_prediction.py", line 21, in __init__
    self.current_vector, self.current_norm = self.GetFeatureVector(image)
  File "/home/uosselab/바탕화면/X_TWICE_AI/image_prediction.py", line 26, in GetFeatureVector
    trans_image = self.transform(image).to(self.cuda)
  File "/home/uosselab/.local/lib/python3.6/site-packages/torchvision/transforms/transforms.py", line 60, in __call__
    img = t(img)
  File "/home/uosselab/.local/lib/python3.6/site-packages/torch/nn/modules/module.py", line 889, in _call_impl
    result = self.forward(*input, **kwargs)
  File "/home/uosselab/.local/lib/python3.6/site-packages/torchvision/transforms/transforms.py", line 273, in forward
    return F.resize(img, self.size, self.interpolation)
  File "/home/uosselab/.local/lib/python3.6/site-packages/torchvision/transforms/functional.py", line 375, in resize
    return F_pil.resize(img, size=size, interpolation=pil_interpolation)
  File "/home/uosselab/.local/lib/python3.6/site-packages/torchvision/transforms/functional_pil.py", line 209, in resize
    raise TypeError('img should be PIL Image. Got {}'.format(type(img)))
TypeError: img should be PIL Image. Got <class 'werkzeug.datastructures.FileStorage'>
[2021-08-25 16:30:39 +0900] [20702] [ERROR] Connection in use: ('0.0.0.0', 8000)
[2021-08-25 16:30:39 +0900] [20702] [ERROR] Retrying in 1 second.
[2021-08-25 16:30:40,486] ERROR in app: Exception on /predict [POST]
Traceback (most recent call last):
  File "/home/uosselab/.local/lib/python3.6/site-packages/flask/app.py", line 2311, in wsgi_app
    response = self.full_dispatch_request()
  File "/home/uosselab/.local/lib/python3.6/site-packages/flask/app.py", line 1834, in full_dispatch_request
    rv = self.handle_user_exception(e)
  File "/home/uosselab/.local/lib/python3.6/site-packages/flask/app.py", line 1737, in handle_user_exception
    reraise(exc_type, exc_value, tb)
  File "/home/uosselab/.local/lib/python3.6/site-packages/flask/_compat.py", line 36, in reraise
    raise value
  File "/home/uosselab/.local/lib/python3.6/site-packages/flask/app.py", line 1832, in full_dispatch_request
    rv = self.dispatch_request()
  File "/home/uosselab/.local/lib/python3.6/site-packages/flask/app.py", line 1818, in dispatch_request
    return self.view_functions[rule.endpoint](**req.view_args)
  File "/home/uosselab/바탕화면/X_TWICE_AI/server.py", line 55, in predict
    '''
  File "/home/uosselab/바탕화면/X_TWICE_AI/image_prediction.py", line 21, in __init__
    self.current_vector, self.current_norm = self.GetFeatureVector(image)
  File "/home/uosselab/바탕화면/X_TWICE_AI/image_prediction.py", line 26, in GetFeatureVector
    trans_image = self.transform(image).to(self.cuda)
  File "/home/uosselab/.local/lib/python3.6/site-packages/torchvision/transforms/transforms.py", line 60, in __call__
    img = t(img)
  File "/home/uosselab/.local/lib/python3.6/site-packages/torch/nn/modules/module.py", line 889, in _call_impl
    result = self.forward(*input, **kwargs)
  File "/home/uosselab/.local/lib/python3.6/site-packages/torchvision/transforms/transforms.py", line 273, in forward
    return F.resize(img, self.size, self.interpolation)
  File "/home/uosselab/.local/lib/python3.6/site-packages/torchvision/transforms/functional.py", line 375, in resize
    return F_pil.resize(img, size=size, interpolation=pil_interpolation)
  File "/home/uosselab/.local/lib/python3.6/site-packages/torchvision/transforms/functional_pil.py", line 209, in resize
    raise TypeError('img should be PIL Image. Got {}'.format(type(img)))
TypeError: img should be PIL Image. Got <class 'werkzeug.datastructures.FileStorage'>
[2021-08-25 16:30:40 +0900] [20702] [ERROR] Connection in use: ('0.0.0.0', 8000)
[2021-08-25 16:30:40 +0900] [20702] [ERROR] Retrying in 1 second.
[2021-08-25 16:30:41 +0900] [20702] [ERROR] Can't connect to ('0.0.0.0', 8000)
[2021-08-25 16:30:42,213] ERROR in app: Exception on /predict [POST]
Traceback (most recent call last):
  File "/home/uosselab/.local/lib/python3.6/site-packages/flask/app.py", line 2311, in wsgi_app
    response = self.full_dispatch_request()
  File "/home/uosselab/.local/lib/python3.6/site-packages/flask/app.py", line 1834, in full_dispatch_request
    rv = self.handle_user_exception(e)
  File "/home/uosselab/.local/lib/python3.6/site-packages/flask/app.py", line 1737, in handle_user_exception
    reraise(exc_type, exc_value, tb)
  File "/home/uosselab/.local/lib/python3.6/site-packages/flask/_compat.py", line 36, in reraise
    raise value
  File "/home/uosselab/.local/lib/python3.6/site-packages/flask/app.py", line 1832, in full_dispatch_request
    rv = self.dispatch_request()
  File "/home/uosselab/.local/lib/python3.6/site-packages/flask/app.py", line 1818, in dispatch_request
    return self.view_functions[rule.endpoint](**req.view_args)
  File "/home/uosselab/바탕화면/X_TWICE_AI/server.py", line 55, in predict
    '''
  File "/home/uosselab/바탕화면/X_TWICE_AI/image_prediction.py", line 21, in __init__
    self.current_vector, self.current_norm = self.GetFeatureVector(image)
  File "/home/uosselab/바탕화면/X_TWICE_AI/image_prediction.py", line 26, in GetFeatureVector
    trans_image = self.transform(image).to(self.cuda)
  File "/home/uosselab/.local/lib/python3.6/site-packages/torchvision/transforms/transforms.py", line 60, in __call__
    img = t(img)
  File "/home/uosselab/.local/lib/python3.6/site-packages/torch/nn/modules/module.py", line 889, in _call_impl
    result = self.forward(*input, **kwargs)
  File "/home/uosselab/.local/lib/python3.6/site-packages/torchvision/transforms/transforms.py", line 273, in forward
    return F.resize(img, self.size, self.interpolation)
  File "/home/uosselab/.local/lib/python3.6/site-packages/torchvision/transforms/functional.py", line 375, in resize
    return F_pil.resize(img, size=size, interpolation=pil_interpolation)
  File "/home/uosselab/.local/lib/python3.6/site-packages/torchvision/transforms/functional_pil.py", line 209, in resize
    raise TypeError('img should be PIL Image. Got {}'.format(type(img)))
TypeError: img should be PIL Image. Got <class 'werkzeug.datastructures.FileStorage'>
[2021-08-25 16:30:47 +0900] [20436] [INFO] Handling signal: term
[2021-08-25 16:30:47 +0900] [20439] [INFO] Worker exiting (pid: 20439)
[2021-08-25 16:30:47 +0900] [20436] [INFO] Shutting down: Master
[2021-08-25 16:30:48 +0900] [20728] [INFO] Starting gunicorn 20.1.0
[2021-08-25 16:30:48 +0900] [20728] [INFO] Listening at: http://0.0.0.0:8000 (20728)
[2021-08-25 16:30:48 +0900] [20728] [INFO] Using worker: sync
[2021-08-25 16:30:48 +0900] [20731] [INFO] Booting worker with pid: 20731
[2021-08-25 16:30:50,281] ERROR in app: Exception on /predict [POST]
Traceback (most recent call last):
  File "/home/uosselab/.local/lib/python3.6/site-packages/flask/app.py", line 2311, in wsgi_app
    response = self.full_dispatch_request()
  File "/home/uosselab/.local/lib/python3.6/site-packages/flask/app.py", line 1834, in full_dispatch_request
    rv = self.handle_user_exception(e)
  File "/home/uosselab/.local/lib/python3.6/site-packages/flask/app.py", line 1737, in handle_user_exception
    reraise(exc_type, exc_value, tb)
  File "/home/uosselab/.local/lib/python3.6/site-packages/flask/_compat.py", line 36, in reraise
    raise value
  File "/home/uosselab/.local/lib/python3.6/site-packages/flask/app.py", line 1832, in full_dispatch_request
    rv = self.dispatch_request()
  File "/home/uosselab/.local/lib/python3.6/site-packages/flask/app.py", line 1818, in dispatch_request
    return self.view_functions[rule.endpoint](**req.view_args)
  File "/home/uosselab/바탕화면/X_TWICE_AI/server.py", line 52, in predict
    class_id, class_name = get_prediction(image_bytes=img_bytes)
  File "/home/uosselab/바탕화면/X_TWICE_AI/server.py", line 40, in get_prediction
    predicted_idx = str(y_hat.item())
ValueError: only one element tensors can be converted to Python scalars
[2021-08-25 16:30:54,517] ERROR in app: Exception on /predict [POST]
Traceback (most recent call last):
  File "/home/uosselab/.local/lib/python3.6/site-packages/flask/app.py", line 2311, in wsgi_app
    response = self.full_dispatch_request()
  File "/home/uosselab/.local/lib/python3.6/site-packages/flask/app.py", line 1834, in full_dispatch_request
    rv = self.handle_user_exception(e)
  File "/home/uosselab/.local/lib/python3.6/site-packages/flask/app.py", line 1737, in handle_user_exception
    reraise(exc_type, exc_value, tb)
  File "/home/uosselab/.local/lib/python3.6/site-packages/flask/_compat.py", line 36, in reraise
    raise value
  File "/home/uosselab/.local/lib/python3.6/site-packages/flask/app.py", line 1832, in full_dispatch_request
    rv = self.dispatch_request()
  File "/home/uosselab/.local/lib/python3.6/site-packages/flask/app.py", line 1818, in dispatch_request
    return self.view_functions[rule.endpoint](**req.view_args)
  File "/home/uosselab/바탕화면/X_TWICE_AI/server.py", line 52, in predict
    class_id, class_name = get_prediction(image_bytes=img_bytes)
  File "/home/uosselab/바탕화면/X_TWICE_AI/server.py", line 40, in get_prediction
    predicted_idx = str(y_hat.item())
ValueError: only one element tensors can be converted to Python scalars
[2021-08-25 16:31:45 +0900] [20728] [CRITICAL] WORKER TIMEOUT (pid:20731)
[2021-08-25 16:31:45 +0900] [20731] [INFO] Worker exiting (pid: 20731)
[2021-08-25 16:31:45 +0900] [20788] [INFO] Booting worker with pid: 20788
[2021-08-25 16:32:03,992] ERROR in app: Exception on /predict [POST]
Traceback (most recent call last):
  File "/home/uosselab/.local/lib/python3.6/site-packages/flask/app.py", line 2311, in wsgi_app
    response = self.full_dispatch_request()
  File "/home/uosselab/.local/lib/python3.6/site-packages/flask/app.py", line 1834, in full_dispatch_request
    rv = self.handle_user_exception(e)
  File "/home/uosselab/.local/lib/python3.6/site-packages/flask/app.py", line 1737, in handle_user_exception
    reraise(exc_type, exc_value, tb)
  File "/home/uosselab/.local/lib/python3.6/site-packages/flask/_compat.py", line 36, in reraise
    raise value
  File "/home/uosselab/.local/lib/python3.6/site-packages/flask/app.py", line 1832, in full_dispatch_request
    rv = self.dispatch_request()
  File "/home/uosselab/.local/lib/python3.6/site-packages/flask/app.py", line 1818, in dispatch_request
    return self.view_functions[rule.endpoint](**req.view_args)
  File "/home/uosselab/바탕화면/X_TWICE_AI/server.py", line 52, in predict
    class_id, class_name = get_prediction(image_bytes=img_bytes)
  File "/home/uosselab/바탕화면/X_TWICE_AI/server.py", line 40, in get_prediction
    predicted_idx = str(y_hat.item())
ValueError: only one element tensors can be converted to Python scalars
[2021-08-25 16:32:15,229] ERROR in app: Exception on /predict [POST]
Traceback (most recent call last):
  File "/home/uosselab/.local/lib/python3.6/site-packages/flask/app.py", line 2311, in wsgi_app
    response = self.full_dispatch_request()
  File "/home/uosselab/.local/lib/python3.6/site-packages/flask/app.py", line 1834, in full_dispatch_request
    rv = self.handle_user_exception(e)
  File "/home/uosselab/.local/lib/python3.6/site-packages/flask/app.py", line 1737, in handle_user_exception
    reraise(exc_type, exc_value, tb)
  File "/home/uosselab/.local/lib/python3.6/site-packages/flask/_compat.py", line 36, in reraise
    raise value
  File "/home/uosselab/.local/lib/python3.6/site-packages/flask/app.py", line 1832, in full_dispatch_request
    rv = self.dispatch_request()
  File "/home/uosselab/.local/lib/python3.6/site-packages/flask/app.py", line 1818, in dispatch_request
    return self.view_functions[rule.endpoint](**req.view_args)
  File "/home/uosselab/바탕화면/X_TWICE_AI/server.py", line 52, in predict
    class_id, class_name = get_prediction(image_bytes=img_bytes)
  File "/home/uosselab/바탕화면/X_TWICE_AI/server.py", line 40, in get_prediction
    predicted_idx = str(y_hat.item())
ValueError: only one element tensors can be converted to Python scalars
[2021-08-25 16:33:00,920] ERROR in app: Exception on /predict [POST]
Traceback (most recent call last):
  File "/home/uosselab/.local/lib/python3.6/site-packages/flask/app.py", line 2311, in wsgi_app
    response = self.full_dispatch_request()
  File "/home/uosselab/.local/lib/python3.6/site-packages/flask/app.py", line 1834, in full_dispatch_request
    rv = self.handle_user_exception(e)
  File "/home/uosselab/.local/lib/python3.6/site-packages/flask/app.py", line 1737, in handle_user_exception
    reraise(exc_type, exc_value, tb)
  File "/home/uosselab/.local/lib/python3.6/site-packages/flask/_compat.py", line 36, in reraise
    raise value
  File "/home/uosselab/.local/lib/python3.6/site-packages/flask/app.py", line 1832, in full_dispatch_request
    rv = self.dispatch_request()
  File "/home/uosselab/.local/lib/python3.6/site-packages/flask/app.py", line 1818, in dispatch_request
    return self.view_functions[rule.endpoint](**req.view_args)
  File "/home/uosselab/바탕화면/X_TWICE_AI/server.py", line 52, in predict
    class_id, class_name = get_prediction(image_bytes=img_bytes)
  File "/home/uosselab/바탕화면/X_TWICE_AI/server.py", line 40, in get_prediction
    predicted_idx = str(y_hat.item())
ValueError: only one element tensors can be converted to Python scalars
[2021-08-25 16:34:44,540] ERROR in app: Exception on /predict [POST]
Traceback (most recent call last):
  File "/home/uosselab/.local/lib/python3.6/site-packages/flask/app.py", line 2311, in wsgi_app
    response = self.full_dispatch_request()
  File "/home/uosselab/.local/lib/python3.6/site-packages/flask/app.py", line 1834, in full_dispatch_request
    rv = self.handle_user_exception(e)
  File "/home/uosselab/.local/lib/python3.6/site-packages/flask/app.py", line 1737, in handle_user_exception
    reraise(exc_type, exc_value, tb)
  File "/home/uosselab/.local/lib/python3.6/site-packages/flask/_compat.py", line 36, in reraise
    raise value
  File "/home/uosselab/.local/lib/python3.6/site-packages/flask/app.py", line 1832, in full_dispatch_request
    rv = self.dispatch_request()
  File "/home/uosselab/.local/lib/python3.6/site-packages/flask/app.py", line 1818, in dispatch_request
    return self.view_functions[rule.endpoint](**req.view_args)
  File "/home/uosselab/바탕화면/X_TWICE_AI/server.py", line 52, in predict
    class_id, class_name = get_prediction(image_bytes=img_bytes)
  File "/home/uosselab/바탕화면/X_TWICE_AI/server.py", line 40, in get_prediction
    predicted_idx = str(y_hat.item())
ValueError: only one element tensors can be converted to Python scalars
[2021-08-25 16:34:55 +0900] [20728] [INFO] Handling signal: term
[2021-08-25 16:34:55 +0900] [20788] [INFO] Worker exiting (pid: 20788)
[2021-08-25 16:34:55 +0900] [20728] [INFO] Shutting down: Master
[2021-08-25 16:34:56 +0900] [20903] [INFO] Starting gunicorn 20.1.0
[2021-08-25 16:34:56 +0900] [20903] [INFO] Listening at: http://0.0.0.0:8000 (20903)
[2021-08-25 16:34:56 +0900] [20903] [INFO] Using worker: sync
[2021-08-25 16:34:56 +0900] [20906] [INFO] Booting worker with pid: 20906
[2021-08-25 16:36:47 +0900] [20903] [INFO] Handling signal: term
[2021-08-25 16:36:47 +0900] [20906] [INFO] Worker exiting (pid: 20906)
[2021-08-25 16:36:47 +0900] [20903] [INFO] Shutting down: Master
[2021-08-25 16:36:48 +0900] [21031] [INFO] Starting gunicorn 20.1.0
[2021-08-25 16:36:48 +0900] [21031] [INFO] Listening at: http://0.0.0.0:8000 (21031)
[2021-08-25 16:36:48 +0900] [21031] [INFO] Using worker: sync
[2021-08-25 16:36:48 +0900] [21034] [INFO] Booting worker with pid: 21034
[2021-08-25 16:36:52,564] ERROR in app: Exception on /predict [POST]
Traceback (most recent call last):
  File "/home/uosselab/.local/lib/python3.6/site-packages/flask/app.py", line 2311, in wsgi_app
    response = self.full_dispatch_request()
  File "/home/uosselab/.local/lib/python3.6/site-packages/flask/app.py", line 1834, in full_dispatch_request
    rv = self.handle_user_exception(e)
  File "/home/uosselab/.local/lib/python3.6/site-packages/flask/app.py", line 1737, in handle_user_exception
    reraise(exc_type, exc_value, tb)
  File "/home/uosselab/.local/lib/python3.6/site-packages/flask/_compat.py", line 36, in reraise
    raise value
  File "/home/uosselab/.local/lib/python3.6/site-packages/flask/app.py", line 1832, in full_dispatch_request
    rv = self.dispatch_request()
  File "/home/uosselab/.local/lib/python3.6/site-packages/flask/app.py", line 1818, in dispatch_request
    return self.view_functions[rule.endpoint](**req.view_args)
  File "/home/uosselab/바탕화면/X_TWICE_AI/server.py", line 56, in predict
    prediction = Image_Prediction(PATH, file)
  File "/home/uosselab/바탕화면/X_TWICE_AI/image_prediction.py", line 21, in __init__
    self.current_vector, self.current_norm = self.GetFeatureVector(image)
  File "/home/uosselab/바탕화면/X_TWICE_AI/image_prediction.py", line 26, in GetFeatureVector
    trans_image = self.transform(image).to(self.cuda)
  File "/home/uosselab/.local/lib/python3.6/site-packages/torchvision/transforms/transforms.py", line 60, in __call__
    img = t(img)
  File "/home/uosselab/.local/lib/python3.6/site-packages/torch/nn/modules/module.py", line 889, in _call_impl
    result = self.forward(*input, **kwargs)
  File "/home/uosselab/.local/lib/python3.6/site-packages/torchvision/transforms/transforms.py", line 273, in forward
    return F.resize(img, self.size, self.interpolation)
  File "/home/uosselab/.local/lib/python3.6/site-packages/torchvision/transforms/functional.py", line 375, in resize
    return F_pil.resize(img, size=size, interpolation=pil_interpolation)
  File "/home/uosselab/.local/lib/python3.6/site-packages/torchvision/transforms/functional_pil.py", line 209, in resize
    raise TypeError('img should be PIL Image. Got {}'.format(type(img)))
TypeError: img should be PIL Image. Got <class 'werkzeug.datastructures.FileStorage'>
[2021-08-25 16:39:25 +0900] [21031] [INFO] Handling signal: term
[2021-08-25 16:39:25 +0900] [21034] [INFO] Worker exiting (pid: 21034)
[2021-08-25 16:39:26 +0900] [21031] [INFO] Shutting down: Master
[2021-08-25 16:39:27 +0900] [21344] [INFO] Starting gunicorn 20.1.0
[2021-08-25 16:39:27 +0900] [21344] [INFO] Listening at: http://0.0.0.0:8000 (21344)
[2021-08-25 16:39:27 +0900] [21344] [INFO] Using worker: sync
[2021-08-25 16:39:27 +0900] [21347] [INFO] Booting worker with pid: 21347
[2021-08-25 16:39:47 +0900] [21344] [INFO] Handling signal: term
[2021-08-25 16:39:47 +0900] [21347] [INFO] Worker exiting (pid: 21347)
[2021-08-25 16:39:47 +0900] [21344] [INFO] Shutting down: Master
[2021-08-25 16:39:49 +0900] [21402] [INFO] Starting gunicorn 20.1.0
[2021-08-25 16:39:49 +0900] [21402] [INFO] Listening at: http://0.0.0.0:8000 (21402)
[2021-08-25 16:39:49 +0900] [21402] [INFO] Using worker: sync
[2021-08-25 16:39:49 +0900] [21405] [INFO] Booting worker with pid: 21405
[2021-08-25 16:39:59 +0900] [21405] [INFO] Worker exiting (pid: 21405)
[2021-08-25 16:39:59 +0900] [21402] [INFO] Handling signal: term
[2021-08-25 16:39:59 +0900] [21402] [INFO] Shutting down: Master
[2021-08-25 16:40:00 +0900] [21464] [INFO] Starting gunicorn 20.1.0
[2021-08-25 16:40:00 +0900] [21464] [INFO] Listening at: http://0.0.0.0:8000 (21464)
[2021-08-25 16:40:00 +0900] [21464] [INFO] Using worker: sync
[2021-08-25 16:40:00 +0900] [21467] [INFO] Booting worker with pid: 21467
[2021-08-25 16:41:38 +0900] [21464] [INFO] Handling signal: term
[2021-08-25 16:41:38 +0900] [21467] [INFO] Worker exiting (pid: 21467)
[2021-08-25 16:41:38 +0900] [21464] [INFO] Shutting down: Master
[2021-08-25 16:41:39 +0900] [21594] [INFO] Starting gunicorn 20.1.0
[2021-08-25 16:41:39 +0900] [21594] [INFO] Listening at: http://0.0.0.0:8000 (21594)
[2021-08-25 16:41:39 +0900] [21594] [INFO] Using worker: sync
[2021-08-25 16:41:39 +0900] [21597] [INFO] Booting worker with pid: 21597
[2021-08-25 16:41:41,212] ERROR in app: Exception on /predict [POST]
Traceback (most recent call last):
  File "/home/uosselab/.local/lib/python3.6/site-packages/flask/app.py", line 2311, in wsgi_app
    response = self.full_dispatch_request()
  File "/home/uosselab/.local/lib/python3.6/site-packages/flask/app.py", line 1834, in full_dispatch_request
    rv = self.handle_user_exception(e)
  File "/home/uosselab/.local/lib/python3.6/site-packages/flask/app.py", line 1737, in handle_user_exception
    reraise(exc_type, exc_value, tb)
  File "/home/uosselab/.local/lib/python3.6/site-packages/flask/_compat.py", line 36, in reraise
    raise value
  File "/home/uosselab/.local/lib/python3.6/site-packages/flask/app.py", line 1832, in full_dispatch_request
    rv = self.dispatch_request()
  File "/home/uosselab/.local/lib/python3.6/site-packages/flask/app.py", line 1818, in dispatch_request
    return self.view_functions[rule.endpoint](**req.view_args)
  File "/home/uosselab/바탕화면/X_TWICE_AI/server.py", line 55, in predict
    prediction = Image_Prediction(PATH, file)
NameError: name 'PATH' is not defined
[2021-08-25 16:42:20 +0900] [21597] [INFO] Worker exiting (pid: 21597)
[2021-08-25 16:42:20 +0900] [21594] [INFO] Handling signal: term
[2021-08-25 16:42:20 +0900] [21594] [INFO] Shutting down: Master
[2021-08-25 16:42:21 +0900] [21703] [INFO] Starting gunicorn 20.1.0
[2021-08-25 16:42:21 +0900] [21703] [INFO] Listening at: http://0.0.0.0:8000 (21703)
[2021-08-25 16:42:21 +0900] [21703] [INFO] Using worker: sync
[2021-08-25 16:42:21 +0900] [21706] [INFO] Booting worker with pid: 21706
[2021-08-25 16:42:22,615] ERROR in app: Exception on /predict [POST]
Traceback (most recent call last):
  File "/home/uosselab/.local/lib/python3.6/site-packages/flask/app.py", line 2311, in wsgi_app
    response = self.full_dispatch_request()
  File "/home/uosselab/.local/lib/python3.6/site-packages/flask/app.py", line 1834, in full_dispatch_request
    rv = self.handle_user_exception(e)
  File "/home/uosselab/.local/lib/python3.6/site-packages/flask/app.py", line 1737, in handle_user_exception
    reraise(exc_type, exc_value, tb)
  File "/home/uosselab/.local/lib/python3.6/site-packages/flask/_compat.py", line 36, in reraise
    raise value
  File "/home/uosselab/.local/lib/python3.6/site-packages/flask/app.py", line 1832, in full_dispatch_request
    rv = self.dispatch_request()
  File "/home/uosselab/.local/lib/python3.6/site-packages/flask/app.py", line 1818, in dispatch_request
    return self.view_functions[rule.endpoint](**req.view_args)
  File "/home/uosselab/바탕화면/X_TWICE_AI/server.py", line 56, in predict
    prediction = Image_Prediction(PATH, image)
NameError: name 'PATH' is not defined
[2021-08-25 16:42:52 +0900] [21703] [INFO] Handling signal: term
[2021-08-25 16:42:52 +0900] [21706] [INFO] Worker exiting (pid: 21706)
[2021-08-25 16:42:53 +0900] [21703] [INFO] Shutting down: Master
[2021-08-25 16:42:53 +0900] [21794] [INFO] Starting gunicorn 20.1.0
[2021-08-25 16:42:53 +0900] [21794] [INFO] Listening at: http://0.0.0.0:8000 (21794)
[2021-08-25 16:42:53 +0900] [21794] [INFO] Using worker: sync
[2021-08-25 16:42:53 +0900] [21797] [INFO] Booting worker with pid: 21797
[2021-08-25 16:42:54,977] ERROR in app: Exception on /predict [POST]
Traceback (most recent call last):
  File "/home/uosselab/.local/lib/python3.6/site-packages/flask/app.py", line 2311, in wsgi_app
    response = self.full_dispatch_request()
  File "/home/uosselab/.local/lib/python3.6/site-packages/flask/app.py", line 1834, in full_dispatch_request
    rv = self.handle_user_exception(e)
  File "/home/uosselab/.local/lib/python3.6/site-packages/flask/app.py", line 1737, in handle_user_exception
    reraise(exc_type, exc_value, tb)
  File "/home/uosselab/.local/lib/python3.6/site-packages/flask/_compat.py", line 36, in reraise
    raise value
  File "/home/uosselab/.local/lib/python3.6/site-packages/flask/app.py", line 1832, in full_dispatch_request
    rv = self.dispatch_request()
  File "/home/uosselab/.local/lib/python3.6/site-packages/flask/app.py", line 1818, in dispatch_request
    return self.view_functions[rule.endpoint](**req.view_args)
  File "/home/uosselab/바탕화면/X_TWICE_AI/server.py", line 56, in predict
    prediction = Image_Prediction(PATH, image)
NameError: name 'PATH' is not defined
[2021-08-25 16:42:56,339] ERROR in app: Exception on /predict [POST]
Traceback (most recent call last):
  File "/home/uosselab/.local/lib/python3.6/site-packages/flask/app.py", line 2311, in wsgi_app
    response = self.full_dispatch_request()
  File "/home/uosselab/.local/lib/python3.6/site-packages/flask/app.py", line 1834, in full_dispatch_request
    rv = self.handle_user_exception(e)
  File "/home/uosselab/.local/lib/python3.6/site-packages/flask/app.py", line 1737, in handle_user_exception
    reraise(exc_type, exc_value, tb)
  File "/home/uosselab/.local/lib/python3.6/site-packages/flask/_compat.py", line 36, in reraise
    raise value
  File "/home/uosselab/.local/lib/python3.6/site-packages/flask/app.py", line 1832, in full_dispatch_request
    rv = self.dispatch_request()
  File "/home/uosselab/.local/lib/python3.6/site-packages/flask/app.py", line 1818, in dispatch_request
    return self.view_functions[rule.endpoint](**req.view_args)
  File "/home/uosselab/바탕화면/X_TWICE_AI/server.py", line 56, in predict
    prediction = Image_Prediction(PATH, image)
NameError: name 'PATH' is not defined
[2021-08-25 16:42:57,069] ERROR in app: Exception on /predict [POST]
Traceback (most recent call last):
  File "/home/uosselab/.local/lib/python3.6/site-packages/flask/app.py", line 2311, in wsgi_app
    response = self.full_dispatch_request()
  File "/home/uosselab/.local/lib/python3.6/site-packages/flask/app.py", line 1834, in full_dispatch_request
    rv = self.handle_user_exception(e)
  File "/home/uosselab/.local/lib/python3.6/site-packages/flask/app.py", line 1737, in handle_user_exception
    reraise(exc_type, exc_value, tb)
  File "/home/uosselab/.local/lib/python3.6/site-packages/flask/_compat.py", line 36, in reraise
    raise value
  File "/home/uosselab/.local/lib/python3.6/site-packages/flask/app.py", line 1832, in full_dispatch_request
    rv = self.dispatch_request()
  File "/home/uosselab/.local/lib/python3.6/site-packages/flask/app.py", line 1818, in dispatch_request
    return self.view_functions[rule.endpoint](**req.view_args)
  File "/home/uosselab/바탕화면/X_TWICE_AI/server.py", line 56, in predict
    prediction = Image_Prediction(PATH, image)
NameError: name 'PATH' is not defined
[2021-08-25 16:42:57,771] ERROR in app: Exception on /predict [POST]
Traceback (most recent call last):
  File "/home/uosselab/.local/lib/python3.6/site-packages/flask/app.py", line 2311, in wsgi_app
    response = self.full_dispatch_request()
  File "/home/uosselab/.local/lib/python3.6/site-packages/flask/app.py", line 1834, in full_dispatch_request
    rv = self.handle_user_exception(e)
  File "/home/uosselab/.local/lib/python3.6/site-packages/flask/app.py", line 1737, in handle_user_exception
    reraise(exc_type, exc_value, tb)
  File "/home/uosselab/.local/lib/python3.6/site-packages/flask/_compat.py", line 36, in reraise
    raise value
  File "/home/uosselab/.local/lib/python3.6/site-packages/flask/app.py", line 1832, in full_dispatch_request
    rv = self.dispatch_request()
  File "/home/uosselab/.local/lib/python3.6/site-packages/flask/app.py", line 1818, in dispatch_request
    return self.view_functions[rule.endpoint](**req.view_args)
  File "/home/uosselab/바탕화면/X_TWICE_AI/server.py", line 56, in predict
    prediction = Image_Prediction(PATH, image)
NameError: name 'PATH' is not defined
[2021-08-25 16:43:22 +0900] [21797] [INFO] Worker exiting (pid: 21797)
[2021-08-25 16:43:22 +0900] [21794] [INFO] Handling signal: term
[2021-08-25 16:43:22 +0900] [21794] [INFO] Shutting down: Master
[2021-08-25 16:43:22 +0900] [21856] [INFO] Starting gunicorn 20.1.0
[2021-08-25 16:43:22 +0900] [21856] [INFO] Listening at: http://0.0.0.0:8000 (21856)
[2021-08-25 16:43:22 +0900] [21856] [INFO] Using worker: sync
[2021-08-25 16:43:22 +0900] [21859] [INFO] Booting worker with pid: 21859
[2021-08-25 16:43:23,892] ERROR in app: Exception on /predict [POST]
Traceback (most recent call last):
  File "/home/uosselab/.local/lib/python3.6/site-packages/flask/app.py", line 2311, in wsgi_app
    response = self.full_dispatch_request()
  File "/home/uosselab/.local/lib/python3.6/site-packages/flask/app.py", line 1834, in full_dispatch_request
    rv = self.handle_user_exception(e)
  File "/home/uosselab/.local/lib/python3.6/site-packages/flask/app.py", line 1737, in handle_user_exception
    reraise(exc_type, exc_value, tb)
  File "/home/uosselab/.local/lib/python3.6/site-packages/flask/_compat.py", line 36, in reraise
    raise value
  File "/home/uosselab/.local/lib/python3.6/site-packages/flask/app.py", line 1832, in full_dispatch_request
    rv = self.dispatch_request()
  File "/home/uosselab/.local/lib/python3.6/site-packages/flask/app.py", line 1818, in dispatch_request
    return self.view_functions[rule.endpoint](**req.view_args)
  File "/home/uosselab/바탕화면/X_TWICE_AI/server.py", line 56, in predict
    prediction = Image_Prediction(PATH, image)
NameError: name 'PATH' is not defined
[2021-08-25 16:43:40,558] ERROR in app: Exception on /predict [POST]
Traceback (most recent call last):
  File "/home/uosselab/.local/lib/python3.6/site-packages/flask/app.py", line 2311, in wsgi_app
    response = self.full_dispatch_request()
  File "/home/uosselab/.local/lib/python3.6/site-packages/flask/app.py", line 1834, in full_dispatch_request
    rv = self.handle_user_exception(e)
  File "/home/uosselab/.local/lib/python3.6/site-packages/flask/app.py", line 1737, in handle_user_exception
    reraise(exc_type, exc_value, tb)
  File "/home/uosselab/.local/lib/python3.6/site-packages/flask/_compat.py", line 36, in reraise
    raise value
  File "/home/uosselab/.local/lib/python3.6/site-packages/flask/app.py", line 1832, in full_dispatch_request
    rv = self.dispatch_request()
  File "/home/uosselab/.local/lib/python3.6/site-packages/flask/app.py", line 1818, in dispatch_request
    return self.view_functions[rule.endpoint](**req.view_args)
  File "/home/uosselab/바탕화면/X_TWICE_AI/server.py", line 56, in predict
    prediction = Image_Prediction('./My_model/New_Vgg_16.pt', image)
NameError: name 'PATH' is not defined
[2021-08-25 16:43:42 +0900] [21856] [INFO] Handling signal: term
[2021-08-25 16:43:42 +0900] [21859] [INFO] Worker exiting (pid: 21859)
[2021-08-25 16:43:42 +0900] [21856] [INFO] Shutting down: Master
[2021-08-25 16:43:43 +0900] [21928] [INFO] Starting gunicorn 20.1.0
[2021-08-25 16:43:43 +0900] [21928] [INFO] Listening at: http://0.0.0.0:8000 (21928)
[2021-08-25 16:43:43 +0900] [21928] [INFO] Using worker: sync
[2021-08-25 16:43:43 +0900] [21931] [INFO] Booting worker with pid: 21931
[2021-08-25 16:44:38 +0900] [21931] [INFO] Worker exiting (pid: 21931)
[2021-08-25 16:44:38 +0900] [21928] [INFO] Handling signal: term
[2021-08-25 16:44:39 +0900] [21928] [INFO] Shutting down: Master
[2021-08-25 16:44:39 +0900] [22036] [INFO] Starting gunicorn 20.1.0
[2021-08-25 16:44:39 +0900] [22036] [INFO] Listening at: http://0.0.0.0:8000 (22036)
[2021-08-25 16:44:39 +0900] [22036] [INFO] Using worker: sync
[2021-08-25 16:44:39 +0900] [22039] [INFO] Booting worker with pid: 22039
[2021-08-25 16:44:59 +0900] [22039] [INFO] Worker exiting (pid: 22039)
[2021-08-25 16:44:59 +0900] [22036] [INFO] Handling signal: term
[2021-08-25 16:44:59 +0900] [22036] [INFO] Shutting down: Master
[2021-08-25 16:45:00 +0900] [22104] [INFO] Starting gunicorn 20.1.0
[2021-08-25 16:45:00 +0900] [22104] [INFO] Listening at: http://0.0.0.0:8000 (22104)
[2021-08-25 16:45:00 +0900] [22104] [INFO] Using worker: sync
[2021-08-25 16:45:00 +0900] [22107] [INFO] Booting worker with pid: 22107
[2021-08-25 16:45:16 +0900] [22107] [INFO] Worker exiting (pid: 22107)
[2021-08-25 16:45:16 +0900] [22104] [INFO] Handling signal: term
[2021-08-25 16:45:16 +0900] [22104] [INFO] Shutting down: Master
[2021-08-25 16:45:17 +0900] [22171] [INFO] Starting gunicorn 20.1.0
[2021-08-25 16:45:17 +0900] [22171] [INFO] Listening at: http://0.0.0.0:8000 (22171)
[2021-08-25 16:45:17 +0900] [22171] [INFO] Using worker: sync
[2021-08-25 16:45:17 +0900] [22174] [INFO] Booting worker with pid: 22174
[2021-08-25 16:45:21,945] ERROR in app: Exception on /predict [POST]
Traceback (most recent call last):
  File "/home/uosselab/.local/lib/python3.6/site-packages/flask/app.py", line 2311, in wsgi_app
    response = self.full_dispatch_request()
  File "/home/uosselab/.local/lib/python3.6/site-packages/flask/app.py", line 1834, in full_dispatch_request
    rv = self.handle_user_exception(e)
  File "/home/uosselab/.local/lib/python3.6/site-packages/flask/app.py", line 1737, in handle_user_exception
    reraise(exc_type, exc_value, tb)
  File "/home/uosselab/.local/lib/python3.6/site-packages/flask/_compat.py", line 36, in reraise
    raise value
  File "/home/uosselab/.local/lib/python3.6/site-packages/flask/app.py", line 1832, in full_dispatch_request
    rv = self.dispatch_request()
  File "/home/uosselab/.local/lib/python3.6/site-packages/flask/app.py", line 1818, in dispatch_request
    return self.view_functions[rule.endpoint](**req.view_args)
  File "/home/uosselab/바탕화면/X_TWICE_AI/server.py", line 62, in predict
    return jsonify({ 'picture_vector': result[0] })
  File "/home/uosselab/.local/lib/python3.6/site-packages/flask/json/__init__.py", line 351, in jsonify
    dumps(data, indent=indent, separators=separators) + '\n',
  File "/home/uosselab/.local/lib/python3.6/site-packages/flask/json/__init__.py", line 194, in dumps
    rv = _json.dumps(obj, **kwargs)
  File "/usr/lib/python3.6/json/__init__.py", line 238, in dumps
    **kw).encode(obj)
  File "/usr/lib/python3.6/json/encoder.py", line 199, in encode
    chunks = self.iterencode(o, _one_shot=True)
  File "/usr/lib/python3.6/json/encoder.py", line 257, in iterencode
    return _iterencode(o, 0)
  File "/home/uosselab/.local/lib/python3.6/site-packages/flask/json/__init__.py", line 81, in default
    return _json.JSONEncoder.default(self, o)
  File "/usr/lib/python3.6/json/encoder.py", line 180, in default
    o.__class__.__name__)
TypeError: Object of type 'ndarray' is not JSON serializable
[2021-08-25 16:45:39 +0900] [22171] [INFO] Handling signal: term
[2021-08-25 16:45:39 +0900] [22174] [INFO] Worker exiting (pid: 22174)
[2021-08-25 16:45:39 +0900] [22171] [INFO] Shutting down: Master
[2021-08-25 16:45:41 +0900] [22249] [INFO] Starting gunicorn 20.1.0
[2021-08-25 16:45:41 +0900] [22249] [INFO] Listening at: http://0.0.0.0:8000 (22249)
[2021-08-25 16:45:41 +0900] [22249] [INFO] Using worker: sync
[2021-08-25 16:45:41 +0900] [22252] [INFO] Booting worker with pid: 22252
[2021-08-25 16:46:14 +0900] [22249] [INFO] Handling signal: term
[2021-08-25 16:46:14 +0900] [22252] [INFO] Worker exiting (pid: 22252)
[2021-08-25 16:46:14 +0900] [22249] [INFO] Shutting down: Master
[2021-08-25 16:46:15 +0900] [22317] [INFO] Starting gunicorn 20.1.0
[2021-08-25 16:46:15 +0900] [22317] [INFO] Listening at: http://0.0.0.0:8000 (22317)
[2021-08-25 16:46:15 +0900] [22317] [INFO] Using worker: sync
[2021-08-25 16:46:15 +0900] [22320] [INFO] Booting worker with pid: 22320
[2021-08-25 16:46:40 +0900] [22317] [INFO] Handling signal: term
[2021-08-25 16:46:40 +0900] [22320] [INFO] Worker exiting (pid: 22320)
[2021-08-25 16:46:40 +0900] [22317] [INFO] Shutting down: Master
[2021-08-25 16:46:41 +0900] [22385] [INFO] Starting gunicorn 20.1.0
[2021-08-25 16:46:41 +0900] [22385] [INFO] Listening at: http://0.0.0.0:8000 (22385)
[2021-08-25 16:46:41 +0900] [22385] [INFO] Using worker: sync
[2021-08-25 16:46:41 +0900] [22388] [INFO] Booting worker with pid: 22388
